Workbook

Sheet ALL STOCK
A1: FILM STOCK 30TH APRIL 26
A2: ITEMTYPE | B2: ITEMSUBTYPE | C2: ITEMCODE | D2: ITEMNAME | E2: THICKNESS | F2: WIDTH | G2: STORESTOCK | H2: QCHOLD | I2: LAST30CONS | J2: PENDINGPO | K2: QCPENDING | L2: PROCESSSTOCK | M2: PENDINGMOVEMENT | N2: Total Stock
A3: BOPP | B3: BOPP TAPE GRADE | C3: 101558 | D3: 21MIC X 760MM TAPE GRADE BOPP | E3: 21 | F3: 760 | G3: 0 | H3: 0 | I3: 0 | J3: 0 | K3: 0 | L3: 72.2 | M3: 0 | N3: 72.2
A4: BOPP | B4: BOPP TAPE GRADE | C4: 101398 | D4: 21MIC X 990MM TAPE GRADE BOPP | E4: 21 | F4: 990 | G4: 1409.28 | H4: 0 | I4: 0 | J4: 0 | K4: 0 | L4: 0 | M4: 0 | N4: 1409.28
A5: BOPP | B5: BOPP TAPE GRADE | C5: 105164 | D5: 21MIC X 1050MM TAPE GRADE BOPP | E5: 21 | F5: 1050 | G5: 212.7 | H5: 0 | I5: 1004.17 | J5: 3000 | K5: 0 | L5: 0 | M5: 0 | N5: 212.7
A6: BOPP | B6: BOPP TAPE GRADE | C6: 105182 | D6: 21MIC X 1200MM TAPE GRADE BOPP | E6: 21 | F6: 1200 | G6: 1454.94 | H6: 0 | I6: 0 | J6: 500 | K6: 0 | L6: 0 | M6: 0 | N6: 1454.94
A7: BOPP | B7: BOPP TRANS BST | C7: 104237 | D7: 8MIC X 785MM TPT BOPP BST | E7: 8 | F7: 785 | G7: 115 | H7: 0 | I7: 0 | J7: 0 | K7: 0 | L7: 0 | M7: 0 | N7: 115
A8: BOPP | B8: BOPP TRANS BST | C8: 104787 | D8: 12MIC X 949MM TPT BOPP BST | E8: 12 | F8: 949 | G8: 2650.96 | H8: 0 | I8: 3094.29 | J8: 574.46 | K8: 0 | L8: 0 | M8: 0 | N8: 2650.96
A9: BOPP | B9: BOPP TRANS BST | C9: 101016 | D9: 12MIC X 970MM TPT BOPP BST | E9: 12 | F9: 970 | G9: 3296.95 | H9: 0 | I9: 521.55 | J9: 33.5 | K9: 0 | L9: 0 | M9: 0 | N9: 3296.95
A10: BOPP | B10: BOPP TRANS BST | C10: 100197 | D10: 12MIC X 1005MM TPT BOPP BST | E10: 12 | F10: 1005 | G10: 291.72 | H10: 0 | I10: 0 | J10: 0 | K10: 0 | L10: 0 | M10: 286.6 | N10: 578.32
A11: BOPP | B11: BOPP TRANS BST | C11: 105114 | D11: 12MIC X 1075MM TPT BOPP BST | E11: 12 | F11: 1075 | G11: 1781.95 | H11: 0 | I11: 714.74 | J11: 0 | K11: 0 | L11: 0 | M11: 0 | N11: 1781.95
A12: BOPP | B12: BOPP TRANS BST | C12: 100199 | D12: 12MIC X 1080MM TPT BOPP BST | E12: 12 | F12: 1080 | G12: 802 | H12: 0 | I12: 795.4 | J12: 0 | K12: 0 | L12: 0 | M12: 0 | N12: 802
A13: BOPP | B13: BOPP TRANS BST | C13: 105113 | D13: 12MIC X 1109MM TPT BOPP BST | E13: 12 | F13: 1109 | G13: 3410.05 | H13: 0 | I13: 0 | J13: 620 | K13: 0 | L13: 0 | M13: 0 | N13: 3410.05
A14: BOPP | B14: BOPP TRANS BST | C14: 103662 | D14: 12MIC X 1125MM TPT BOPP BST | E14: 12 | F14: 1125 | G14: 0 | H14: 0 | I14: 0 | J14: 1750 | K14: 0 | L14: 0 | M14: 0 | N14: 0
... A321: POLYESTER | B321: POLYESTER(PLAIN) | C321: 103307 | D321: 10MIC X 1165MM PLAIN PET | E321: 10 | F321: 1165 | G321: 0 | H321: 0 | I321: 0 | J321: 0 | K321: 0 | L321: 104 | M321: 0 | N321: 104
A322: LASTRECEIPTDATE | B322: ITEMTYPE | C322: ITEMCODE | D322: ITEMNAME | E322: THICK | F322: WIDTH | G322: STORESTOCK | H322: QCHOLD | I322: LAST31CONS | J322: OPENORDER_KG | K322: PENDINGINDENT | L322: PROCESSSTOCK | M322: PENDINGMOVEMENT | N322: Total Stock
A323: 46028 | B323: PE(N) | C323: 102620 | D323: 18MIC X 1000MM NATURAL PE (NF) | E323: 18 | F323: 1000 | G323: 383.8 | H323: 0 | I323: 0 | J323: 0 | K323: 0 | L323: 0 | M323: 0 | N323: 383.8
A324: 46015 | B324: PE(N) | C324: 105012 | D324: 18MIC X 1071MM NATURAL PE (NF PEPSICO) | E324: 18 | F324: 1071 | G324: 61 | H324: 0 | I324: 0 | J324: 0 | K324: 0 | L324: 0 | M324: 0 | N324: 61
A325: 46067 | B325: PE(N) | C325: 104921 | D325: 18MIC X 1100MM NATURAL PE (NF BINGO) | E325: 18 | F325: 1100 | G325: 217 | H325: 0 | I325: 0 | J325: 0 | K325: 0 | L325: 0 | M325: 0 | N325: 217
A326: 45979 | B326: PE(N) | C326: 103668 | D326: 18MIC X 1115MM NATURAL PE (NF) | E326: 18 | F326: 1115 | G326: 160 | H326: 0 | I326: 0 | J326: 0 | K326: 0 | L326: 267 | M326: 0 | N326: 427
A327: 46130 | B327: PE(N) | C327: 104647 | D327: 18MIC X 1245MM NATURAL PE(NF BINGO) | E327: 18 | F327: 1245 | G327: 2468.7 | H327: 0 | I327: 0 | J327: 30000 | K327: 0 | L327: 0 | M327: 0 | N327: 2468.7
A328: 46118 | B328: PE(N) | C328: 103961 | D328: 20MIC X 705MM NATURAL PE(BREAD) | E328: 20 | F328: 705 | G328: 95.8 | H328: 0 | I328: 0 | J328: 0 | K328: 0 | L328: 0 | M328: 107 | N328: 202.8
A329: 46075 | B329: PE(N) | C329: 103461 | D329: 20MIC X 795MM NATURAL PE (FLOW WRAP-DISPOVAN) | E329: 20 | F329: 795 | G329: 132 | H329: 0 | I329: 0 | J329: 0 | K329: 0 | L329: 0 | M329: 0 | N329: 132
A330: 46118 | B330: PE(N) | C330: 105165 | D330: 20MIC X 815MM NATURAL PE(FLOW WRAP- DISPOVAN) | E330: 20 | F330: 815 | G330: 68 | H330: 0 | I330: 0 | J330: 0 | K330: 0 | L330: 0 | M330: 0 | N330: 68
A331: 46107 | B331: PE(N) | C331: 104019 | D331: 20MIC X 975MM NATURAL PE (CANDY OUTER) | E331: 20 | F331: 975 | G331: 56 | H331: 0 | I331: 0 | J331: 0 | K331: 0 | L331: 0 | M331: 0 | N331: 56
A332: 46026 | B332: PE(N) | C332: 100290 | D332: 20MIC X 1095MM NATURAL PE (NF) | E332: 20 | F332: 1095 | G332: 200 | H332: 0 | I332: 0 | J332: 0 | K332: 0 | L332: 0 | M332: 0 | N332: 200
A333: 46098 | B333: PE(N) | C333: 104175 | D333: 20MIC X 1190MM NATURAL PE (NF) | E333: 20 | F333: 1190 | G333: 1223.6 | H333: 0 | I333: 0 | J333: 0 | K333: 0 | L333: 0 | M333: 0 | N333: 1223.6
A334: 46129 | B334: PE(N) | C334: 103832 | D334: 21MIC X 855MM NATURAL PE (NF) | E334: 21 | F334: 855 | G334: 181 | H334: 0 | I334: 0 | J334: 0 | K334: 0 | L334: 0 | M334: 0 | N334: 181
... A373: 46067 | B373: PE(N) | C373: 100805 | D373: 30MIC X 870MM NATURAL PE (NF) | E373: 30 | F373: 870 | G373: 349 | H373: 0 | I373: 0 | J373: 0 | K373: 0 | L373: 0 | M373: 0 | N373: 349
B374: PE(N) | C374: 105213 | D374: 30MIC X 870MM NATURAL PE(TATA TEA) | E374: 30 | F374: 870 | G374: 453 | H374: 0 | I374: 0 | J374: 0 | K374: 0 | L374: 0 | M374: 0 | N374: 453
A375: 46134 | B375: PE(N) | C375: 104317 | D375: 30MIC X 885MM NATURAL PE (SALT POLY/SELANT GRADE) | E375: 30 | F375: 885 | G375: 3349.6 | H375: 0 | I375: 0 | J375: 1805.4 | K375: 1805.4 | L375: 0 | M375: 0 | N375: 3349.6
A376: 46134 | B376: PE(N) | C376: 103658 | D376: 30MIC X 915MM NATURAL PE (SEASONING) | E376: 30 | F376: 915 | G376: 263 | H376: 0 | I376: 0 | J376: 0 | K376: 0 | L376: 0 | M376: 0 | N376: 263
A377: 46070 | B377: PE(N) | C377: 104195 | D377: 30MIC X 915MM NATURAL PE (SOYABARI NF) | E377: 30 | F377: 915 | G377: 184 | H377: 0 | I377: 0 | J377: 0 | K377: 0 | L377: 0 | M377: 0 | N377: 184
A378: 46134 | B378: PE(N) | C378: 103404 | D378: 30MIC X 975MM NATURAL PE (NF) | E378: 30 | F378: 975 | G378: 193 | H378: 0 | I378: 0 | J378: 0 | K378: 0 | L378: 0 | M378: 0 | N378: 193
A379: 46117 | B379: PE(N) | C379: 105224 | D379: 30MIC X 1005MM NATURAL PE(TATA TEA) | E379: 30 | F379: 1005 | G379: 1233.2 | H379: 0 | I379: 0 | J379: 0 | K379: 0 | L379: 0 | M379: 0 | N379: 1233.2
A380: 46011 | B380: PE(N) | C380: 104806 | D380: 30MIC X 1050MM NATURAL PE(NF) | E380: 30 | F380: 1050 | G380: 156 | H380: 0 | I380: 0 | J380: 0 | K380: 0 | L380: 0 | M380: 0 | N380: 156
A381: 46086 | B381: PE(N) | C381: 100064 | D381: 32.5MIC X 705MM NATURAL PE ( TEA ) | E381: 32.5 | F381: 705 | G381: 100 | H381: 0 | I381: 0 | J381: 450 | K381: 0 | L381: 0 | M381: 0 | N381: 100
A382: 46040 | B382: PE(N) | C382: 103791 | D382: 32.5MIC X 1115MM NATURAL PE (NF-BINGO) | E382: 32.5 | F382: 1115 | G382: 591.8 | H382: 0 | I382: 0 | J382: 0 | K382: 0 | L382: 0 | M382: 0 | N382: 591.8
A383: 46116 | B383: PE(N) | C383: 101708 | D383: 35MIC X 655MM NATURAL PE (TEA) | E383: 35 | F383: 655 | G383: 71.4 | H383: 0 | I383: 0 | J383: 0 | K383: 0 | L383: 0 | M383: 0 | N383: 71.4
A384: 46115 | B384: PE(N) | C384: 104885 | D384: 35MIC X 1215MM NATURAL PE(NF) | E384: 35 | F384: 1215 | G384: 406.2 | H384: 0 | I384: 0 | J384: 0 | K384: 0 | L384: 95 | M384: 0 | N384: 501.2
...

Sheet BOOKING
A1: PARTY NAME | B1: SO DATE | C1: ITEM CODE | D1: ITEM NAME | E1: UOM | F1: QTY | G1: ORDER NO | H1: JOB GROUP | I1: JOB TYPE | J1: NAME | K1: ORDER TYPE | L1: DELIVERY DATE | N1: =B1 -> SO DATE
A2: PARTY-1 | B2: 46141 | C2: 1005 | D2: JOB NAME-1 | E2: KGS | F2: 1000 | G2: SO-1 | H2: LAMINATE ROLL 4PLY | I2: SNACKS | J2: SALES PERSON NAME | K2: REPEAT | L2: 46157 | N2: =B2 -> 46141
A3: PARTY-2 | B3: 46141 | C3: 1006 | D3: JOB NAME-2 | E3: KGS | F3: 1000 | G3: SO-2 | H3: POLY ROLL 1PLY | I3: OIL | J3: SALES PERSON NAME | K3: REPEAT | L3: 46157 | N3: =B3 -> 46141
A4: PARTY-3 | B4: 46141 | C4: 1007 | D4: JOB NAME-3 | E4: KGS | F4: 1000 | G4: SO-3 | H4: LAMINATE ROLL 3PLY | I4: BISCUITS | J4: SALES PERSON NAME | K4: REPEAT | L4: 46157 | N4: =B4 -> 46141
A5: PARTY-4 | B5: 46141 | C5: 1008 | D5: JOB NAME-4 | E5: KGS | F5: 1000 | G5: SO-4 | H5: LAMINATE ROLL 3PLY | I5: FLOW WRAP | J5: SALES PERSON NAME | K5: REPEAT | L5: 46157 | N5: =B5 -> 46141
A6: PARTY-5 | B6: 46141 | C6: 1009 | D6: JOB NAME-5 | E6: PCS | F6: 75000 | G6: SO-5 | H6: LAMINATE ROLL 3PLY | I6: TEA | J6: SALES PERSON NAME | K6: REPEAT | L6: 46157 | N6: =B6 -> 46141
A7: PARTY-6 | B7: 46141 | C7: 1010 | D7: JOB NAME-6 | E7: KGS | F7: 1000 | G7: SO-6 | H7: LAMINATE ROLL 2PLY | I7: FLOW WRAP | J7: SALES PERSON NAME | K7: NEW | L7: 46157 | N7: =B7 -> 46141
N8: =B8 -> 0
N9: =B9 -> 0
N10: =B10 -> 0

Sheet ORDER BOOK
A1: Order Booking -2021 | F1: ORDER BOOKING | I1: 5 | J1: last clear 22 SEPT | K1: 3 | L1: 4 | M1: 5 | O1: 7 | P1: 8 | Q1: 9 | R1: 10 | S1: 11 | T1: 12 | U1: 13 | V1: 14 | W1: 15 | X1: 16 | Y1: 17 | Z1: 18
A2: STATUS | B2: YEAR | C2: MONTH | D2: FG NO | E2: MKT | F2: ORDER DATE | G2: DELV.DATE | H2: EXP.TAT | I2: So No | J2: JOB NAME | K2: WO/no | L2: PKD | M2: FG.Code | N2: OBB | O2: Roll/Pouch | P2: Qty(Nos) | Q2: Qty(Kgs) | R2: CUSTOMER | S2: TYPE | T2: FINAL SLITTED | U2: R/P | W2: SO DATE | X2: DELIVERY | Y2: GRADE
B3: 2022 | D3: 1005 | F3: =VLOOKUP(I3,BOOKING!$G$1:$N$6584,8,0) -> 46141 | G3: =VLOOKUP(I3,BOOKING!$G$1:$L$6314,6,0) -> 46157 | H3: =$G3-$F3 -> 16 | I3: SO-1 | J3: =VLOOKUP(D3,'Spec Sheet (2)'!$B$4:$GM$49,194,0) -> JOB NAME-1 | K3: C-1 | M3: =VLOOKUP(J3,'Spec Sheet (2)'!$A$4:$C$26703,2,0) -> 1005 | O3: =VLOOKUP(J3,'Spec Sheet (2)'!$A$4:$ED$15568,134,0) -> Roll | Q3: 1000 | R3: =VLOOKUP(J3,'Spec Sheet (2)'!$A$4:$D$26649,4,0) -> PARTY-1 | S3: =VLOOKUP(J3,'Spec Sheet (2)'!$A$4:$GD$23938,186,0) -> SNACKS | V3: =H3 -> 16 | W3: =F3 -> 46141 | X3: =G3 -> 46157 | Y3: =VLOOKUP(M3,'Spec Sheet (2)'!$B$4:$GD$9,185) -> SNACKS
B4: 2022 | D4: 1006 | F4: =VLOOKUP(I4,BOOKING!$G$1:$N$6584,8,0) -> 46141 | G4: =VLOOKUP(I4,BOOKING!$G$1:$L$6314,6,0) -> 46157 | H4: =$G4-$F4 -> 16 | I4: SO-2 | J4: =VLOOKUP(D4,'Spec Sheet (2)'!$B$4:$GM$49,194,0) -> JOB NAME-2 | K4: C-2 | M4: =VLOOKUP(J4,'Spec Sheet (2)'!$A$4:$C$26703,2,0) -> 1006 | O4: =VLOOKUP(J4,'Spec Sheet (2)'!$A$4:$ED$15568,134,0) -> Roll | Q4: 1000 | R4: =VLOOKUP(J4,'Spec Sheet (2)'!$A$4:$D$26649,4,0) -> PARTY-2 | S4: =VLOOKUP(J4,'Spec Sheet (2)'!$A$4:$GD$23938,186,0) -> OIL SURFACE | V4: =H4 -> 16 | W4: =F4 -> 46141 | X4: =G4 -> 46157 | Y4: =VLOOKUP(M4,'Spec Sheet (2)'!$B$4:$GD$9,185) -> OIL SURFACE
B5: 2022 | D5: 1007 | F5: =VLOOKUP(I5,BOOKING!$G$1:$N$6584,8,0) -> 46141 | G5: =VLOOKUP(I5,BOOKING!$G$1:$L$6314,6,0) -> 46157 | H5: =$G5-$F5 -> 16 | I5: SO-3 | J5: =VLOOKUP(D5,'Spec Sheet (2)'!$B$4:$GM$49,194,0) -> JOB NAME-3 | K5: C-3 | M5: =VLOOKUP(J5,'Spec Sheet (2)'!$A$4:$C$26703,2,0) -> 1007 | O5: =VLOOKUP(J5,'Spec Sheet (2)'!$A$4:$ED$15568,134,0) -> Roll | Q5: 1000 | R5: =VLOOKUP(J5,'Spec Sheet (2)'!$A$4:$D$26649,4,0) -> PARTY-3 | S5: =VLOOKUP(J5,'Spec Sheet (2)'!$A$4:$GD$23938,186,0) -> BISCUITE | V5: =H5 -> 16 | W5: =F5 -> 46141 | X5: =G5 -> 46157 | Y5: =VLOOKUP(M5,'Spec Sheet (2)'!$B$4:$GD$9,185) -> BISCUITE
B6: 2022 | D6: 1008 | F6: =VLOOKUP(I6,BOOKING!$G$1:$N$6584,8,0) -> 46141 | G6: =VLOOKUP(I6,BOOKING!$G$1:$L$6314,6,0) -> 46157 | H6: =$G6-$F6 -> 16 | I6: SO-4 | J6: =VLOOKUP(D6,'Spec Sheet (2)'!$B$4:$GM$49,194,0) -> JOB NAME-4 | K6: C-4 | M6: =VLOOKUP(J6,'Spec Sheet (2)'!$A$4:$C$26703,2,0) -> 1008 | O6: =VLOOKUP(J6,'Spec Sheet (2)'!$A$4:$ED$15568,134,0) -> Roll | Q6: 1000 | R6: =VLOOKUP(J6,'Spec Sheet (2)'!$A$4:$D$26649,4,0) -> PARTY-4 | S6: =VLOOKUP(J6,'Spec Sheet (2)'!$A$4:$GD$23938,186,0) -> FLOW WRAP | V6: =H6 -> 16 | W6: =F6 -> 46141 | X6: =G6 -> 46157 | Y6: =VLOOKUP(M6,'Spec Sheet (2)'!$B$4:$GD$9,185) -> FLOW WRAP
B7: 2022 | D7: 1009 | F7: =VLOOKUP(I7,BOOKING!$G$1:$N$6584,8,0) -> 46141 | G7: =VLOOKUP(I7,BOOKING!$G$1:$L$6314,6,0) -> 46157 | H7: =$G7-$F7 -> 16 | I7: SO-5 | J7: =VLOOKUP(D7,'Spec Sheet (2)'!$B$4:$GM$49,194,0) -> JOB NAME-5 | K7: C-5 | M7: =VLOOKUP(J7,'Spec Sheet (2)'!$A$4:$C$26703,2,0) -> 1009 | O7: =VLOOKUP(J7,'Spec Sheet (2)'!$A$4:$ED$15568,134,0) -> Roll | P7: 75000 | Q7: 862.5 | R7: =VLOOKUP(J7,'Spec Sheet (2)'!$A$4:$D$26649,4,0) -> PARTY-5 | S7: =VLOOKUP(J7,'Spec Sheet (2)'!$A$4:$GD$23938,186,0) -> SPICE | V7: =H7 -> 16 | W7: =F7 -> 46141 | X7: =G7 -> 46157 | Y7: =VLOOKUP(M7,'Spec Sheet (2)'!$B$4:$GD$9,185) -> SPICE
B8: 2022 | D8: 1010 | F8: =VLOOKUP(I8,BOOKING!$G$1:$N$6584,8,0) -> 46141 | G8: =VLOOKUP(I8,BOOKING!$G$1:$L$6314,6,0) -> 46157 | H8: =$G8-$F8 -> 16 | I8: SO-6 | J8: =VLOOKUP(D8,'Spec Sheet (2)'!$B$4:$GM$49,194,0) -> JOB NAME-6 | K8: C-6 | M8: =VLOOKUP(J8,'Spec Sheet (2)'!$A$4:$C$26703,2,0) -> 1010 | O8: =VLOOKUP(J8,'Spec Sheet (2)'!$A$4:$ED$15568,134,0) -> Roll | Q8: 1000 | R8: =VLOOKUP(J8,'Spec Sheet (2)'!$A$4:$D$26649,4,0) -> PARTY-6 | S8: =VLOOKUP(J8,'Spec Sheet (2)'!$A$4:$GD$23938,186,0) -> FLOW WRAP | V8: =H8 -> 16 | W8: =F8 -> 46141 | X8: =G8 -> 46157 | Y8: =VLOOKUP(M8,'Spec Sheet (2)'!$B$4:$GD$9,185) -> FLOW WRAP
B9: 2022 | F9: =VLOOKUP(I9,BOOKING!$G$1:$N$6584,8,0) -> #N/A | G9: =VLOOKUP(I9,BOOKING!$G$1:$L$6314,6,0) -> #N/A | H9: =$G9-$F9 -> #N/A | J9: =VLOOKUP(D9,'Spec Sheet (2)'!$B$4:$GM$49,194,0) -> #N/A | M9: =VLOOKUP(J9,'Spec Sheet (2)'!$A$4:$C$26703,2,0) -> #N/A | O9: =VLOOKUP(J9,'Spec Sheet (2)'!$A$4:$ED$15568,134,0) -> #N/A | R9: =VLOOKUP(J9,'Spec Sheet (2)'!$A$4:$D$26649,4,0) -> #N/A | S9: =VLOOKUP(J9,'Spec Sheet (2)'!$A$4:$GD$23938,186,0) -> #N/A | V9: =H9 -> #N/A | W9: =F9 -> #N/A | X9: =G9 -> #N/A | Y9: =VLOOKUP(M9,'Spec Sheet (2)'!$B$4:$GD$9,185) -> #N/A
B10: 2022 | F10: =VLOOKUP(I10,BOOKING!$G$1:$N$6584,8,0) -> #N/A | G10: =VLOOKUP(I10,BOOKING!$G$1:$L$6314,6,0) -> #N/A | H10: =$G10-$F10 -> #N/A | J10: =VLOOKUP(D10,'Spec Sheet (2)'!$B$4:$GM$49,194,0) -> #N/A | M10: =VLOOKUP(J10,'Spec Sheet (2)'!$A$4:$C$26703,2,0) -> #N/A | O10: =VLOOKUP(J10,'Spec Sheet (2)'!$A$4:$ED$15568,134,0) -> #N/A | R10: =VLOOKUP(J10,'Spec Sheet (2)'!$A$4:$D$26649,4,0) -> #N/A | S10: =VLOOKUP(J10,'Spec Sheet (2)'!$A$4:$GD$23938,186,0) -> #N/A | V10: =H10 -> #N/A | W10: =F10 -> #N/A | X10: =G10 -> #N/A | Y10: =VLOOKUP(M10,'Spec Sheet (2)'!$B$4:$GD$9,185) -> #N/A
B11: 2022 | F11: =VLOOKUP(I11,BOOKING!$G$1:$N$6584,8,0) -> #N/A | G11: =VLOOKUP(I11,BOOKING!$G$1:$L$6314,6,0) -> #N/A | H11: =$G11-$F11 -> #N/A | J11: =VLOOKUP(D11,'Spec Sheet (2)'!$B$4:$GM$49,194,0) -> #N/A | M11: =VLOOKUP(J11,'Spec Sheet (2)'!$A$4:$C$26703,2,0) -> #N/A | O11: =VLOOKUP(J11,'Spec Sheet (2)'!$A$4:$ED$15568,134,0) -> #N/A | R11: =VLOOKUP(J11,'Spec Sheet (2)'!$A$4:$D$26649,4,0) -> #N/A | S11: =VLOOKUP(J11,'Spec Sheet (2)'!$A$4:$GD$23938,186,0) -> #N/A | V11: =H11 -> #N/A | W11: =F11 -> #N/A | X11: =G11 -> #N/A | Y11: =VLOOKUP(M11,'Spec Sheet (2)'!$B$4:$GD$9,185) -> #N/A
B12: 2022 | F12: =VLOOKUP(I12,BOOKING!$G$1:$N$6584,8,0) -> #N/A | G12: =VLOOKUP(I12,BOOKING!$G$1:$L$6314,6,0) -> #N/A | H12: =$G12-$F12 -> #N/A | J12: =VLOOKUP(D12,'Spec Sheet (2)'!$B$4:$GM$49,194,0) -> #N/A | M12: =VLOOKUP(J12,'Spec Sheet (2)'!$A$4:$C$26703,2,0) -> #N/A | O12: =VLOOKUP(J12,'Spec Sheet (2)'!$A$4:$ED$15568,134,0) -> #N/A | R12: =VLOOKUP(J12,'Spec Sheet (2)'!$A$4:$D$26649,4,0) -> #N/A | S12: =VLOOKUP(J12,'Spec Sheet (2)'!$A$4:$GD$23938,186,0) -> #N/A | V12: =H12 -> #N/A | W12: =F12 -> #N/A | X12: =G12 -> #N/A | Y12: =VLOOKUP(M12,'Spec Sheet (2)'!$B$4:$GD$9,185) -> #N/A
B13: 2022 | F13: =VLOOKUP(I13,BOOKING!$G$1:$N$6584,8,0) -> #N/A | G13: =VLOOKUP(I13,BOOKING!$G$1:$L$6314,6,0) -> #N/A | H13: =$G13-$F13 -> #N/A | J13: =VLOOKUP(D13,'Spec Sheet (2)'!$B$4:$GM$49,194,0) -> #N/A | M13: =VLOOKUP(J13,'Spec Sheet (2)'!$A$4:$C$26703,2,0) -> #N/A | O13: =VLOOKUP(J13,'Spec Sheet (2)'!$A$4:$ED$15568,134,0) -> #N/A | R13: =VLOOKUP(J13,'Spec Sheet (2)'!$A$4:$D$26649,4,0) -> #N/A | S13: =VLOOKUP(J13,'Spec Sheet (2)'!$A$4:$GD$23938,186,0) -> #N/A | V13: =H13 -> #N/A | W13: =F13 -> #N/A | X13: =G13 -> #N/A | Y13: =VLOOKUP(M13,'Spec Sheet (2)'!$B$4:$GD$9,185) -> #N/A
B14: 2022 | F14: =VLOOKUP(I14,BOOKING!$G$1:$N$6584,8,0) -> #N/A | G14: =VLOOKUP(I14,BOOKING!$G$1:$L$6314,6,0) -> #N/A | H14: =$G14-$F14 -> #N/A | J14: =VLOOKUP(D14,'Spec Sheet (2)'!$B$4:$GM$49,194,0) -> #N/A | M14: =VLOOKUP(J14,'Spec Sheet (2)'!$A$4:$C$26703,2,0) -> #N/A | O14: =VLOOKUP(J14,'Spec Sheet (2)'!$A$4:$ED$15568,134,0) -> #N/A | R14: =VLOOKUP(J14,'Spec Sheet (2)'!$A$4:$D$26649,4,0) -> #N/A | S14: =VLOOKUP(J14,'Spec Sheet (2)'!$A$4:$GD$23938,186,0) -> #N/A | V14: =H14 -> #N/A | W14: =F14 -> #N/A | X14: =G14 -> #N/A | Y14: =VLOOKUP(M14,'Spec Sheet (2)'!$B$4:$GD$9,185) -> #N/A
B15: 2022 | F15: =VLOOKUP(I15,BOOKING!$G$1:$N$6584,8,0) -> #N/A | G15: =VLOOKUP(I15,BOOKING!$G$1:$L$6314,6,0) -> #N/A | H15: =$G15-$F15 -> #N/A | J15: =VLOOKUP(D15,'Spec Sheet (2)'!$B$4:$GM$49,194,0) -> #N/A | M15: =VLOOKUP(J15,'Spec Sheet (2)'!$A$4:$C$26703,2,0) -> #N/A | O15: =VLOOKUP(J15,'Spec Sheet (2)'!$A$4:$ED$15568,134,0) -> #N/A | R15: =VLOOKUP(J15,'Spec Sheet (2)'!$A$4:$D$26649,4,0) -> #N/A | S15: =VLOOKUP(J15,'Spec Sheet (2)'!$A$4:$GD$23938,186,0) -> #N/A | V15: =H15 -> #N/A | W15: =F15 -> #N/A | X15: =G15 -> #N/A | Y15: =VLOOKUP(M15,'Spec Sheet (2)'!$B$4:$GD$9,185) -> #N/A
B16: 2022 | F16: =VLOOKUP(I16,BOOKING!$G$1:$N$6584,8,0) -> #N/A | G16: =VLOOKUP(I16,BOOKING!$G$1:$L$6314,6,0) -> #N/A | H16: =$G16-$F16 -> #N/A | J16: =VLOOKUP(D16,'Spec Sheet (2)'!$B$4:$GM$49,194,0) -> #N/A | M16: =VLOOKUP(J16,'Spec Sheet (2)'!$A$4:$C$26703,2,0) -> #N/A | O16: =VLOOKUP(J16,'Spec Sheet (2)'!$A$4:$ED$15568,134,0) -> #N/A | R16: =VLOOKUP(J16,'Spec Sheet (2)'!$A$4:$D$26649,4,0) -> #N/A | S16: =VLOOKUP(J16,'Spec Sheet (2)'!$A$4:$GD$23938,186,0) -> #N/A | V16: =H16 -> #N/A | W16: =F16 -> #N/A | X16: =G16 -> #N/A | Y16: =VLOOKUP(M16,'Spec Sheet (2)'!$B$4:$GD$9,185) -> #N/A
B17: 2022 | F17: =VLOOKUP(I17,BOOKING!$G$1:$N$6584,8,0) -> #N/A | G17: =VLOOKUP(I17,BOOKING!$G$1:$L$6314,6,0) -> #N/A | H17: =$G17-$F17 -> #N/A | J17: =VLOOKUP(D17,'Spec Sheet (2)'!$B$4:$GM$49,194,0) -> #N/A | M17: =VLOOKUP(J17,'Spec Sheet (2)'!$A$4:$C$26703,2,0) -> #N/A | O17: =VLOOKUP(J17,'Spec Sheet (2)'!$A$4:$ED$15568,134,0) -> #N/A | R17: =VLOOKUP(J17,'Spec Sheet (2)'!$A$4:$D$26649,4,0) -> #N/A | S17: =VLOOKUP(J17,'Spec Sheet (2)'!$A$4:$GD$23938,186,0) -> #N/A | V17: =H17 -> #N/A | W17: =F17 -> #N/A | X17: =G17 -> #N/A | Y17: =VLOOKUP(M17,'Spec Sheet (2)'!$B$4:$GD$9,185) -> #N/A
B18: 2022 | F18: =VLOOKUP(I18,BOOKING!$G$1:$N$6584,8,0) -> #N/A | G18: =VLOOKUP(I18,BOOKING!$G$1:$L$6314,6,0) -> #N/A | H18: =$G18-$F18 -> #N/A | J18: =VLOOKUP(D18,'Spec Sheet (2)'!$B$4:$GM$49,194,0) -> #N/A | M18: =VLOOKUP(J18,'Spec Sheet (2)'!$A$4:$C$26703,2,0) -> #N/A | O18: =VLOOKUP(J18,'Spec Sheet (2)'!$A$4:$ED$15568,134,0) -> #N/A | R18: =VLOOKUP(J18,'Spec Sheet (2)'!$A$4:$D$26649,4,0) -> #N/A | S18: =VLOOKUP(J18,'Spec Sheet (2)'!$A$4:$GD$23938,186,0) -> #N/A | V18: =H18 -> #N/A | W18: =F18 -> #N/A | X18: =G18 -> #N/A | Y18: =VLOOKUP(M18,'Spec Sheet (2)'!$B$4:$GD$9,185) -> #N/A

Sheet PENDING ORDER
A1: PENDING ORDER STATUS | L1: 2 | M1: 3 | O1: 5 | P1: 6 | Q1: 7 | R1: 8 | S1: 9 | T1: 10 | U1: 11 | V1: 12 | W1: 13 | X1: 14 | Y1: 15 | Z1: 16 | AA1: 17 | AB1: 18 | AC1: 19 | AD1: 20 | AE1: 21 | AF1: 22 | AG1: 23 | AH1: 24 | AI1: 25 | AJ1: 26 | AK1: 27 | AL1: 28 | AM1: 29 | AN1: 30 | AO1: 31 | AP1: 32 | AQ1: 33 | AR1: 34 | AS1: 35 | AT1: 36 | AU1: 37 | AV1: 38 | AW1: 39 | AX1: 40 | AY1: 41 | AZ1: 42 | BA1: 43 | BB1: 44 | BC1: 45 | BD1: 46 | BE1: 47 | BF1: 48 | BG1: 49 | BH1: 50 | BI1: 51 | BJ1: 52 | BK1: 53 | BL1: 54 | BM1: 55 | BN1: 56 | BO1: 57 | BP1: 58 | BQ1: 59 | BR1: 60 | BS1: 61 | BT1: 62 | BU1: 63 | BV1: 64 | BW1: 65 | BX1: 66 | BY1: 67 | BZ1: 68 | CA1: 69 | CB1: 70 | CC1: 71 | CD1: 72 | CE1: 73 | CF1: 74 | CG1: 75 | CH1: 76 | CI1: 77 | CJ1: 78 | CK1: 79 | CL1: 80 | CM1: 81 | CN1: 82 | CO1: 83 | CP1: 84 | CQ1: 85 | CV1: 90
P2: DATED | Q2: 45537 | T2: TO PRINT | AJ2: PTD | AK2: PTD | AL2: EXTRUSION | AO2: EXT | AQ2: LAM 1 | AT2: LAM1 | AV2: LAM 2 | AY2: LAM2 | BC2: PRN | BK2: LAM 1 | BT2: LAM2
A3: SO No | B3: GRADE | C3: Ptd RM | D3: Lam 1 RM | F3: white PE/SURFACE | G3: FG NO | H3: SO DATE | I3: POUCH | J3: ECL? | K3: SO No | L3: Job Name | M3: ` | N3: REMARKS | O3: SLT-STATUS | P3: Kg Qty | Q3: conv. factor | R3: SALE UNIT | S3: UOM | T3: TARGET Output | U3: KM | V3: X-pected KG | W3: UOM | X3: TOTAL PTD | Y3: KM | Z3: PTG bal | AA3: UOM | AB3: Print Km | AC3: total pending Lamination[wip+not ptd} | AD3: KM | AE3: SLIT WIDTH | AF3: Ext | AG3: Sol Base | AH3: Sol Less | AI3: PTD TRANSFER | AJ3: PTD WIP | AK3: NEXT PROCESS OF PTD | AL3: TARGET | AM3: TOTAL | AN3: TRNS | AO3: EXT WIP | AP3: NEXT OF EXTN | AQ3: TARGET | AR3: TOTAL | AS3: TRANS | AT3: WIP | AU3: NEXT OF LAM 1 | AV3: TARGET | AW3: TOTAL | AX3: TRANS | AY3: WIP | AZ3: NEXT OF LAM 1 | BA3: FOR SLITTING | BB3: 1ST FILM-CODE | BC3: PRINTING- Substrate | BD3: Prn Mic | BE3: Prn Width Mtr | BF3: PRN BOM QTY | BG3: Stock | BH3: APO | BJ3: CODE2 | BK3: LAM-1 RM | BL3: LAM-1 RM Micron | BM3: LAM-1 RM Width in MTR | BN3: LAM-1 RM Qty | BO3: Stock | BP3: APO | BQ3: TPO | BR3: Remark | BS3: LAM TYPE | BT3: LAM-2 RM | BU3: LAM-2 RM Micron | BV3: LAM-2 RM Width in MTR | BW3: LAA-2 RM QTY | BX3: Stock | BY3: APO | BZ3: FG NO | CA3: PLY | CB3: LAM TYPE | CC3: PRN GSM | CD3: SW-1 GSM | CE3: SW-2 GSM | CF3: Ink | CG3: Ist Pass Adh | CH3: 2nd Pass Adh | CI3: Extrusion GSM | CJ3: Extrusion FINAL GSM | CK3: Total GSM | CL3: Std Wastage | CM3: WIDTH | CN3: 1ST LAM GSM | CO3: CUSTOMER | CP3: WO | CQ3: 2ND PASS LAM INPUT
A4: =K4 -> SO-1 | B4: =VLOOKUP(L4,'Spec Sheet (2)'!$A$4:$GD$26703,186,0) -> SNACKS | F4: =VLOOKUP(L4,'Spec Sheet (2)'!$A$4:$S$9,19,0) -> CC Met Pet ( OD 2.2+) | G4: =VLOOKUP(L4,'Spec Sheet (2)'!$A$4:$B$739,2,0) -> 1005 | H4: =VLOOKUP(K4,'ORDER BOOK'!$I$3:$W$18,15,0) -> 46141 | J4: =VLOOKUP(L4,'Spec Sheet (2)'!$A$4:$CV$26703,100,0) -> ECL- Job | K4: SO-1 | L4: JOB NAME-1 | M4: =VLOOKUP(K4,'ORDER BOOK'!$I$3:$K$18,3,0) -> C-1 | O4: =IF(X4+AM4+AR4+AW4=0,"BAL",IF(AJ4+AO4+AT4+AY4=0,"COMPLETED","BAL")) -> BAL | P4: =IF(S4="KG",R4*Q4,R4/1000*Q4) -> 1000 | Q4: 1 | R4: 1000 | S4: KG | T4: =(CC4+CF4)*P4*CL4/CK4 -> 307.30023 | U4: =T4/BE4/(CC4+CF4) -> 15.345829 | V4: =(Y4*AE4*CK4)/1.06 -> 1103.1352 | W4: =+S4 -> KG | X4: 350 | Y4: =X4/BE4/(CC4+CF4) -> 17.478152 | Z4: =IF(T4-X4>0,T4-X4,0) -> 0 | AA4: =+S4 -> KG | AB4: =IF(U4-Y4>0,U4-Y4,0) -> 0 | AC4: =T4-AI4 -> 307.30023 | AD4: =AC4/BE4/(CC4+CF4) -> 15.345829 | AE4: =VLOOKUP(L4,'Spec Sheet (2)'!$A$4:$BE$9,57,0)/1000 -> 1.1 | AF4: =IF(CI4>0,AB4,0) -> 0 | AG4: =(IF(BS4="B",AB4,0)+IF(CB4="B",AB4,0)) -> 0 | AH4: =(IF(BS4="L",AB4,0)+IF(CB4="L",AB4,0)) -> 0 | AI4: 0 | AJ4: =X4-AI4 -> 350 | AK4: =VLOOKUP(L4,'Spec Sheet (2)'!$A$4:$FG$15742,163,0) -> Extrusion | AL4: =CM4*U4*CJ4/1000-3*CM4*U4*CJ4/1000/100 -> 666.49622 | AM4: 0 | AN4: 0 | AO4: =AM4-AN4 -> 0 | AP4: =VLOOKUP(L4,'Spec Sheet (2)'!$A$4:$FH$9,164,0) -> solv.Less | AQ4: =(U4*CM4*CN4/1000) -> 687.1095 | AR4: 0 | AS4: 0 | AT4: =AR4-AS4 -> 0 | AU4: =VLOOKUP(L4,'Spec Sheet (2)'!$A$4:$FI$9,165,0) -> 0 | AV4: =IF(H4="1PLY",0,IF(H4="2PLY",0,U4*CM4*CK4/1000))-2*IF(H4="1PLY",0,IF(H4="2PLY",0,U4*CM4*CK4/1000))/100 -> 1029 | AW4: 0 | AX4: 0 | AY4: =AW4-AX4 -> 0 | AZ4: =VLOOKUP(L4,'Spec Sheet (2)'!$A$4:$FJ$16684,166,0) -> Slitting | BA4: =IF(AK4="Slitting",AJ4,0)+IF(AP4="Slitting",AO4,0)+IF(AU4="Slitting",AT4,0)+IF(AZ4="Slitting",AY4,0) -> 0 | BB4: =VLOOKUP(L4,'Spec Sheet (2)'!$A$4:$AL$3749,38,0) -> 104523 | BC4: =VLOOKUP(L4,'Spec Sheet (2)'!$A$4:$O$26703,15,0) -> 1125mmX12Mic PET Chemical | BD4: =VLOOKUP(L4,'Spec Sheet (2)'!$A$4:$L$26703,11,0) -> 12 | BE4: =VLOOKUP(L4,'Spec Sheet (2)'!$A$4:$J$26703,9,0)/1000 -> 1.125 | BF4: =AB4*BE4*BD4*VLOOKUP(L4,'Spec Sheet (2)'!$A$4:$L$25803,12,0) -> 0 | BG4: =IF(ISNA(VLOOKUP(BB4,'ALL STOCK'!$C$3:$N$990,12,0)),"-",VLOOKUP(BB4,'ALL STOCK'!$C$3:$N$990,12,0)) -> 2672.23 | BH4: =IF(ISNA(VLOOKUP(BB4,'ALL STOCK'!$C$3:$J$990,8,0)),"-",VLOOKUP(BB4,'ALL STOCK'!$C$3:$J$990,8,0)) -> 0 | BJ4: =VLOOKUP(L4,'Spec Sheet (2)'!$A$4:$AM$9,39,0) -> 103714 | BK4: =VLOOKUP(L4,'Spec Sheet (2)'!$A$4:$Z$26703,26,0) -> 1115mmx10mic CC Met Pet ( OD 2.2+) | BL4: =VLOOKUP(L4,'Spec Sheet (2)'!$A$4:$V$9,22,0) -> 10 | BM4: =VLOOKUP(L4,'Spec Sheet (2)'!$A$4:$T$26703,20,0)/1000 -> 1.115 | BN4: =AB4*BM4*CD4 -> 0 | BO4: =IF(ISNA(VLOOKUP(BJ4,'ALL STOCK'!$C$4:$N$990,12,0)),"-",VLOOKUP(BJ4,'ALL STOCK'!$C$4:$N$990,12,0)) -> 1393.82 | BP4: =IF(ISNA(VLOOKUP(BJ4,'ALL STOCK'!$C$4:$J$990,8,0)),"-",VLOOKUP(BJ4,'ALL STOCK'!$C$4:$J$990,8,0)) -> 0 | BR4: =VLOOKUP(L4,'Spec Sheet (2)'!$A$4:$AN$9,40,0) -> 103829 | BS4: =VLOOKUP(L4,'Spec Sheet (2)'!$A$4:$FD$9,160,0) -> E | BT4: =VLOOKUP(L4,'Spec Sheet (2)'!$A$4:$AK$26703,37,0) -> 1115mmX 21mic PE (Natural) | BU4: =VLOOKUP(L4,'Spec Sheet (2)'!$A$4:$AG$26703,33,0) -> 21 | BV4: =VLOOKUP(L4,'Spec Sheet (2)'!$A$4:$AE$26703,31,0)/1000 -> 1.115 | BW4: =AB4*BV4*CE4 -> 0 | BX4: =IF(ISNA(VLOOKUP(BR4,'ALL STOCK'!$C$3:$N$990,12,0)),"-",VLOOKUP(BR4,'ALL STOCK'!$C$3:$N$990,12,0)) -> 5413.6 | BY4: =IF(ISNA(VLOOKUP(BR4,'ALL STOCK'!$C$4:$J$990,8,)),"-",VLOOKUP(BR4,'ALL STOCK'!$C$4:$J$990,8,)) -> 0 | BZ4: =VLOOKUP(L4,'Spec Sheet (2)'!$A$4:$B$25803,2,0) -> 1005 | CA4: =VLOOKUP(L4,'Spec Sheet (2)'!$A$4:$FO$25803,171,0) -> 4PLY | CB4: =VLOOKUP(L4,'Spec Sheet (2)'!$A$4:$FF$9,161,0) -> L | CC4: =VLOOKUP(L4,'Spec Sheet (2)'!$A$4:$M$25803,13,0) -> 16.8 | CD4: =VLOOKUP(L4,'Spec Sheet (2)'!$A$4:$X$26703,24,0) -> 14 | CE4: =VLOOKUP(L4,'Spec Sheet (2)'!$A$4:$AI$25803,35,0) -> 19.32 | CF4: =VLOOKUP(L4,'Spec Sheet (2)'!$A$4:$BF$26703,58,0) -> 1 | CG4: =VLOOKUP(L4,'Spec Sheet (2)'!$A$4:$FN$25803,169,0) -> 0 | CH4: =VLOOKUP(L4,'Spec Sheet (2)'!$A$4:$FN$25803,170,0) -> 1.7 | CI4: =VLOOKUP(L4,'Spec Sheet (2)'!$A$4:$CX$26703,102,0) -> 8 | CJ4: =VLOOKUP(L4,'Spec Sheet (2)'!$A$4:$DC$26703,107,0) -> 39.8 | CK4: =SUM(CC4:CI4) -> 60.82 | CL4: =VLOOKUP(L4,'Spec Sheet (2)'!$A$4:$FL$26703,168,0) -> 1.05 | CM4: =VLOOKUP(L4,'Spec Sheet (2)'!$A$4:$I$26703,9,0) -> 1125 | CN4: =VLOOKUP(L4,'Spec Sheet (2)'!$A$4:$FP$26703,172,0) -> 39.8 | CO4: =VLOOKUP(L4,'Spec Sheet (2)'!$A$4:$D$26703,4,0) -> PARTY-1 | CQ4: =AQ4-AS4 -> 687.1095
A5: =K5 -> SO-2 | B5: =VLOOKUP(L5,'Spec Sheet (2)'!$A$4:$GD$26703,186,0) -> OIL SURFACE | F5: =VLOOKUP(L5,'Spec Sheet (2)'!$A$4:$S$9,19,0) | G5: =VLOOKUP(L5,'Spec Sheet (2)'!$A$4:$B$739,2,0) -> 1006 | H5: =VLOOKUP(K5,'ORDER BOOK'!$I$3:$W$18,15,0) -> 46141 | J5: =VLOOKUP(L5,'Spec Sheet (2)'!$A$4:$CV$26703,100,0) -> - | K5: SO-2 | L5: JOB NAME-2 | M5: =VLOOKUP(K5,'ORDER BOOK'!$I$3:$K$18,3,0) -> C-2 | O5: =IF(X5+AM5+AR5+AW5=0,"BAL",IF(AJ5+AO5+AT5+AY5=0,"COMPLETED","BAL")) -> BAL | P5: =IF(S5="KG",R5*Q5,R5/1000*Q5) -> 1000 | Q5: 1 | R5: 1000 | S5: KG | T5: =(CC5+CF5)*P5*CL5/CK5 -> 1000 | U5: =T5/BE5/(CC5+CF5) -> 10.126967 | V5: =(Y5*AE5*CK5)/1.06 -> 0 | W5: =+S5 -> KG | X5: 0 | Y5: =X5/BE5/(CC5+CF5) -> 0 | Z5: =IF(T5-X5>0,T5-X5,0) -> 1000 | AA5: =+S5 -> KG | AB5: =IF(U5-Y5>0,U5-Y5,0) -> 10.126967 | AC5: =T5-AI5 -> 1000 | AD5: =AC5/BE5/(CC5+CF5) -> 10.126967 | AE5: =VLOOKUP(L5,'Spec Sheet (2)'!$A$4:$BE$9,57,0)/1000 -> 0.975 | AF5: =IF(CI5>0,AB5,0) -> 0 | AG5: =(IF(BS5="B",AB5,0)+IF(CB5="B",AB5,0)) -> 0 | AH5: =(IF(BS5="L",AB5,0)+IF(CB5="L",AB5,0)) -> 0 | AI5: 0 | AJ5: =X5-AI5 -> 0 | AK5: =VLOOKUP(L5,'Spec Sheet (2)'!$A$4:$FG$15742,163,0) -> Slitting | AL5: =CM5*U5*CJ5/1000-3*CM5*U5*CJ5/1000/100 -> 0 | AM5: 0 | AN5: 0 | AO5: =AM5-AN5 -> 0 | AP5: =VLOOKUP(L5,'Spec Sheet (2)'!$A$4:$FH$9,164,0) -> 0 | AQ5: =(U5*CM5*CN5/1000) -> 1000 | AR5: 0 | AS5: 0 | AT5: =AR5-AS5 -> 0 | AU5: =VLOOKUP(L5,'Spec Sheet (2)'!$A$4:$FI$9,165,0) -> 0 | AV5: =IF(H5="1PLY",0,IF(H5="2PLY",0,U5*CM5*CK5/1000))-2*IF(H5="1PLY",0,IF(H5="2PLY",0,U5*CM5*CK5/1000))/100 -> 980 | AW5: 0 | AX5: 0 | AY5: =AW5-AX5 -> 0 | AZ5: =VLOOKUP(L5,'Spec Sheet (2)'!$A$4:$FJ$16684,166,0) -> 0 | BA5: =IF(AK5="Slitting",AJ5,0)+IF(AP5="Slitting",AO5,0)+IF(AU5="Slitting",AT5,0)+IF(AZ5="Slitting",AY5,0) -> 0 | BB5: =VLOOKUP(L5,'Spec Sheet (2)'!$A$4:$AL$3749,38,0) -> 104795 | BC5: =VLOOKUP(L5,'Spec Sheet (2)'!$A$4:$O$26703,15,0) -> 985mmX105Mic PE (White) | BD5: =VLOOKUP(L5,'Spec Sheet (2)'!$A$4:$L$26703,11,0) -> 105 | BE5: =VLOOKUP(L5,'Spec Sheet (2)'!$A$4:$J$26703,9,0)/1000 -> 0.985 | BF5: =AB5*BE5*BD5*VLOOKUP(L5,'Spec Sheet (2)'!$A$4:$L$25803,12,0) -> 995.01247 | BG5: =IF(ISNA(VLOOKUP(BB5,'ALL STOCK'!$C$3:$N$990,12,0)),"-",VLOOKUP(BB5,'ALL STOCK'!$C$3:$N$990,12,0)) -> 5148.9 | BH5: =IF(ISNA(VLOOKUP(BB5,'ALL STOCK'!$C$3:$J$990,8,0)),"-",VLOOKUP(BB5,'ALL STOCK'!$C$3:$J$990,8,0)) -> 0 | BJ5: =VLOOKUP(L5,'Spec Sheet (2)'!$A$4:$AM$9,39,0) -> 0 | BK5: =VLOOKUP(L5,'Spec Sheet (2)'!$A$4:$Z$26703,26,0) -> mmxmic | BL5: =VLOOKUP(L5,'Spec Sheet (2)'!$A$4:$V$9,22,0) -> 0 | BM5: =VLOOKUP(L5,'Spec Sheet (2)'!$A$4:$T$26703,20,0)/1000 -> 0 | BN5: =AB5*BM5*CD5 -> 0 | BO5: =IF(ISNA(VLOOKUP(BJ5,'ALL STOCK'!$C$4:$N$990,12,0)),"-",VLOOKUP(BJ5,'ALL STOCK'!$C$4:$N$990,12,0)) -> - | BP5: =IF(ISNA(VLOOKUP(BJ5,'ALL STOCK'!$C$4:$J$990,8,0)),"-",VLOOKUP(BJ5,'ALL STOCK'!$C$4:$J$990,8,0)) -> - | BR5: =VLOOKUP(L5,'Spec Sheet (2)'!$A$4:$AN$9,40,0) -> 0 | BS5: =VLOOKUP(L5,'Spec Sheet (2)'!$A$4:$FD$9,160,0) -> S | BT5: =VLOOKUP(L5,'Spec Sheet (2)'!$A$4:$AK$26703,37,0) -> mmX mic | BU5: =VLOOKUP(L5,'Spec Sheet (2)'!$A$4:$AG$26703,33,0) -> 0 | BV5: =VLOOKUP(L5,'Spec Sheet (2)'!$A$4:$AE$26703,31,0)/1000 -> 0 | BW5: =AB5*BV5*CE5 -> 0 | BX5: =IF(ISNA(VLOOKUP(BR5,'ALL STOCK'!$C$3:$N$990,12,0)),"-",VLOOKUP(BR5,'ALL STOCK'!$C$3:$N$990,12,0)) -> - | BY5: =IF(ISNA(VLOOKUP(BR5,'ALL STOCK'!$C$4:$J$990,8,)),"-",VLOOKUP(BR5,'ALL STOCK'!$C$4:$J$990,8,)) -> - | BZ5: =VLOOKUP(L5,'Spec Sheet (2)'!$A$4:$B$25803,2,0) -> 1006 | CA5: =VLOOKUP(L5,'Spec Sheet (2)'!$A$4:$FO$25803,171,0) -> 1PLY | CB5: =VLOOKUP(L5,'Spec Sheet (2)'!$A$4:$FF$9,161,0) -> X | CC5: =VLOOKUP(L5,'Spec Sheet (2)'!$A$4:$M$25803,13,0) -> 99.75 | CD5: =VLOOKUP(L5,'Spec Sheet (2)'!$A$4:$X$26703,24,0) -> 0 | CE5: =VLOOKUP(L5,'Spec Sheet (2)'!$A$4:$AI$25803,35,0) -> 0 | CF5: =VLOOKUP(L5,'Spec Sheet (2)'!$A$4:$BF$26703,58,0) -> 0.5 | CG5: =VLOOKUP(L5,'Spec Sheet (2)'!$A$4:$FN$25803,169,0) -> 0 | CH5: =VLOOKUP(L5,'Spec Sheet (2)'!$A$4:$FN$25803,170,0) -> 0 | CI5: =VLOOKUP(L5,'Spec Sheet (2)'!$A$4:$CX$26703,102,0) -> 0 | CJ5: =VLOOKUP(L5,'Spec Sheet (2)'!$A$4:$DC$26703,107,0) -> 0 | CK5: =SUM(CC5:CI5) -> 100.25 | CL5: =VLOOKUP(L5,'Spec Sheet (2)'!$A$4:$FL$26703,168,0) -> 1 | CM5: =VLOOKUP(L5,'Spec Sheet (2)'!$A$4:$I$26703,9,0) -> 985 | CN5: =VLOOKUP(L5,'Spec Sheet (2)'!$A$4:$FP$26703,172,0) -> 100.25 | CO5: =VLOOKUP(L5,'Spec Sheet (2)'!$A$4:$D$26703,4,0) -> PARTY-2 | CQ5: =AQ5-AS5 -> 1000
A6: =K6 -> SO-3 | B6: =VLOOKUP(L6,'Spec Sheet (2)'!$A$4:$GD$26703,186,0) -> BISCUITE | F6: =VLOOKUP(L6,'Spec Sheet (2)'!$A$4:$S$9,19,0) -> Met BOPP(HSL) | G6: =VLOOKUP(L6,'Spec Sheet (2)'!$A$4:$B$739,2,0) -> 1007 | H6: =VLOOKUP(K6,'ORDER BOOK'!$I$3:$W$18,15,0) -> 46141 | J6: =VLOOKUP(L6,'Spec Sheet (2)'!$A$4:$CV$26703,100,0) -> ECL- Job | K6: SO-3 | L6: JOB NAME-3 | M6: =VLOOKUP(K6,'ORDER BOOK'!$I$3:$K$18,3,0) -> C-3 | O6: =IF(X6+AM6+AR6+AW6=0,"BAL",IF(AJ6+AO6+AT6+AY6=0,"COMPLETED","BAL")) -> BAL | P6: =IF(S6="KG",R6*Q6,R6/1000*Q6) -> 1000 | Q6: 1 | R6: 1000 | S6: KG | T6: =(CC6+CF6)*P6*CL6/CK6 -> 344.16667 | U6: =T6/BE6/(CC6+CF6) -> 30.734106 | V6: =(Y6*AE6*CK6)/1.06 -> 0 | W6: =+S6 -> KG | X6: 0 | Y6: =X6/BE6/(CC6+CF6) -> 0 | Z6: =IF(T6-X6>0,T6-X6,0) -> 344.16667 | AA6: =+S6 -> KG | AB6: =IF(U6-Y6>0,U6-Y6,0) -> 30.734106 | AC6: =T6-AI6 -> 344.16667 | AD6: =AC6/BE6/(CC6+CF6) -> 30.734106 | AE6: =VLOOKUP(L6,'Spec Sheet (2)'!$A$4:$BE$9,57,0)/1000 -> 0.924 | AF6: =IF(CI6>0,AB6,0) -> 30.734106 | AG6: =(IF(BS6="B",AB6,0)+IF(CB6="B",AB6,0)) -> 0 | AH6: =(IF(BS6="L",AB6,0)+IF(CB6="L",AB6,0)) -> 0 | AI6: 0 | AJ6: =X6-AI6 -> 0 | AK6: =VLOOKUP(L6,'Spec Sheet (2)'!$A$4:$FG$15742,163,0) -> Extrusion | AL6: =CM6*U6*CJ6/1000-3*CM6*U6*CJ6/1000/100 -> 1018.5 | AM6: 0 | AN6: 0 | AO6: =AM6-AN6 -> 0 | AP6: =VLOOKUP(L6,'Spec Sheet (2)'!$A$4:$FH$9,164,0) -> Slitting | AQ6: =(U6*CM6*CN6/1000) -> 1050 | AR6: 0 | AS6: 0 | AT6: =AR6-AS6 -> 0 | AU6: =VLOOKUP(L6,'Spec Sheet (2)'!$A$4:$FI$9,165,0) -> 0 | AV6: =IF(H6="1PLY",0,IF(H6="2PLY",0,U6*CM6*CK6/1000))-2*IF(H6="1PLY",0,IF(H6="2PLY",0,U6*CM6*CK6/1000))/100 -> 1029 | AW6: 0 | AX6: 0 | AY6: =AW6-AX6 -> 0 | AZ6: =VLOOKUP(L6,'Spec Sheet (2)'!$A$4:$FJ$16684,166,0) -> 0 | BA6: =IF(AK6="Slitting",AJ6,0)+IF(AP6="Slitting",AO6,0)+IF(AU6="Slitting",AT6,0)+IF(AZ6="Slitting",AY6,0) -> 0 | BB6: =VLOOKUP(L6,'Spec Sheet (2)'!$A$4:$AL$3749,38,0) -> 104787 | BC6: =VLOOKUP(L6,'Spec Sheet (2)'!$A$4:$O$26703,15,0) -> 949mmX12Mic BOPP BST | BD6: =VLOOKUP(L6,'Spec Sheet (2)'!$A$4:$L$26703,11,0) -> 12 | BE6: =VLOOKUP(L6,'Spec Sheet (2)'!$A$4:$J$26703,9,0)/1000 -> 0.949 | BF6: =AB6*BE6*BD6*VLOOKUP(L6,'Spec Sheet (2)'!$A$4:$L$25803,12,0) -> 315 | BG6: =IF(ISNA(VLOOKUP(BB6,'ALL STOCK'!$C$3:$N$990,12,0)),"-",VLOOKUP(BB6,'ALL STOCK'!$C$3:$N$990,12,0)) -> 2650.96 | BH6: =IF(ISNA(VLOOKUP(BB6,'ALL STOCK'!$C$3:$J$990,8,0)),"-",VLOOKUP(BB6,'ALL STOCK'!$C$3:$J$990,8,0)) -> 574.46 | BJ6: =VLOOKUP(L6,'Spec Sheet (2)'!$A$4:$AM$9,39,0) -> 104788 | BK6: =VLOOKUP(L6,'Spec Sheet (2)'!$A$4:$Z$26703,26,0) -> 939mmx18mic Met BOPP(HSL) | BL6: =VLOOKUP(L6,'Spec Sheet (2)'!$A$4:$V$9,22,0) -> 18 | BM6: =VLOOKUP(L6,'Spec Sheet (2)'!$A$4:$T$26703,20,0)/1000 -> 0.939 | BN6: =AB6*BM6*CD6 -> 467.52107 | BO6: =IF(ISNA(VLOOKUP(BJ6,'ALL STOCK'!$C$4:$N$990,12,0)),"-",VLOOKUP(BJ6,'ALL STOCK'!$C$4:$N$990,12,0)) -> 4455.23 | BP6: =IF(ISNA(VLOOKUP(BJ6,'ALL STOCK'!$C$4:$J$990,8,0)),"-",VLOOKUP(BJ6,'ALL STOCK'!$C$4:$J$990,8,0)) -> 44.45 | BR6: =VLOOKUP(L6,'Spec Sheet (2)'!$A$4:$AN$9,40,0) -> 0 | BS6: =VLOOKUP(L6,'Spec Sheet (2)'!$A$4:$FD$9,160,0) -> E | BT6: =VLOOKUP(L6,'Spec Sheet (2)'!$A$4:$AK$26703,37,0) -> mmX mic | BU6: =VLOOKUP(L6,'Spec Sheet (2)'!$A$4:$AG$26703,33,0) -> 0 | BV6: =VLOOKUP(L6,'Spec Sheet (2)'!$A$4:$AE$26703,31,0)/1000 -> 0 | BW6: =AB6*BV6*CE6 -> 0 | BX6: =IF(ISNA(VLOOKUP(BR6,'ALL STOCK'!$C$3:$N$990,12,0)),"-",VLOOKUP(BR6,'ALL STOCK'!$C$3:$N$990,12,0)) -> - | BY6: =IF(ISNA(VLOOKUP(BR6,'ALL STOCK'!$C$4:$J$990,8,)),"-",VLOOKUP(BR6,'ALL STOCK'!$C$4:$J$990,8,)) -> - | BZ6: =VLOOKUP(L6,'Spec Sheet (2)'!$A$4:$B$25803,2,0) -> 1007 | CA6: =VLOOKUP(L6,'Spec Sheet (2)'!$A$4:$FO$25803,171,0) -> 3PLY | CB6: =VLOOKUP(L6,'Spec Sheet (2)'!$A$4:$FF$9,161,0) -> X | CC6: =VLOOKUP(L6,'Spec Sheet (2)'!$A$4:$M$25803,13,0) -> 10.8 | CD6: =VLOOKUP(L6,'Spec Sheet (2)'!$A$4:$X$26703,24,0) -> 16.2 | CE6: =VLOOKUP(L6,'Spec Sheet (2)'!$A$4:$AI$25803,35,0) -> 0 | CF6: =VLOOKUP(L6,'Spec Sheet (2)'!$A$4:$BF$26703,58,0) -> 1 | CG6: =VLOOKUP(L6,'Spec Sheet (2)'!$A$4:$FN$25803,169,0) -> 0 | CH6: =VLOOKUP(L6,'Spec Sheet (2)'!$A$4:$FN$25803,170,0) -> 0 | CI6: =VLOOKUP(L6,'Spec Sheet (2)'!$A$4:$CX$26703,102,0) -> 8 | CJ6: =VLOOKUP(L6,'Spec Sheet (2)'!$A$4:$DC$26703,107,0) -> 36 | CK6: =SUM(CC6:CI6) -> 36 | CL6: =VLOOKUP(L6,'Spec Sheet (2)'!$A$4:$FL$26703,168,0) -> 1.05 | CM6: =VLOOKUP(L6,'Spec Sheet (2)'!$A$4:$I$26703,9,0) -> 949 | CN6: =VLOOKUP(L6,'Spec Sheet (2)'!$A$4:$FP$26703,172,0) -> 36 | CO6: =VLOOKUP(L6,'Spec Sheet (2)'!$A$4:$D$26703,4,0) -> PARTY-3 | CQ6: =AQ6-AS6 -> 1050
A7: =K7 -> SO-4 | B7: =VLOOKUP(L7,'Spec Sheet (2)'!$A$4:$GD$26703,186,0) -> FLOW WRAP | F7: =VLOOKUP(L7,'Spec Sheet (2)'!$A$4:$S$9,19,0) -> Met Pet Chemical | G7: =VLOOKUP(L7,'Spec Sheet (2)'!$A$4:$B$739,2,0) -> 1008 | H7: =VLOOKUP(K7,'ORDER BOOK'!$I$3:$W$18,15,0) -> 46141 | J7: =VLOOKUP(L7,'Spec Sheet (2)'!$A$4:$CV$26703,100,0) -> - | K7: SO-4 | L7: JOB NAME-4 | M7: =VLOOKUP(K7,'ORDER BOOK'!$I$3:$K$18,3,0) -> C-4 | O7: =IF(X7+AM7+AR7+AW7=0,"BAL",IF(AJ7+AO7+AT7+AY7=0,"COMPLETED","BAL")) -> BAL | P7: =IF(S7="KG",R7*Q7,R7/1000*Q7) -> 1000 | Q7: 1 | R7: 1000 | S7: KG | T7: =(CC7+CF7)*P7*CL7/CK7 -> 256.29921 | U7: =T7/BE7/(CC7+CF7) -> 17.011762 | V7: =(Y7*AE7*CK7)/1.06 -> 0 | W7: =+S7 -> KG | X7: 0 | Y7: =X7/BE7/(CC7+CF7) -> 0 | Z7: =IF(T7-X7>0,T7-X7,0) -> 256.29921 | AA7: =+S7 -> KG | AB7: =IF(U7-Y7>0,U7-Y7,0) -> 17.011762 | AC7: =T7-AI7 -> 256.29921 | AD7: =AC7/BE7/(CC7+CF7) -> 17.011762 | AE7: =VLOOKUP(L7,'Spec Sheet (2)'!$A$4:$BE$9,57,0)/1000 -> 1.2 | AF7: =IF(CI7>0,AB7,0) -> 0 | AG7: =(IF(BS7="B",AB7,0)+IF(CB7="B",AB7,0)) -> 0 | AH7: =(IF(BS7="L",AB7,0)+IF(CB7="L",AB7,0)) -> 34.023525 | AI7: 0 | AJ7: =X7-AI7 -> 0 | AK7: =VLOOKUP(L7,'Spec Sheet (2)'!$A$4:$FG$15742,163,0) -> solv.Less | AL7: =CM7*U7*CJ7/1000-3*CM7*U7*CJ7/1000/100 -> 0 | AM7: 0 | AN7: 0 | AO7: =AM7-AN7 -> 0 | AP7: =VLOOKUP(L7,'Spec Sheet (2)'!$A$4:$FH$9,164,0) -> 0 | AQ7: =(U7*CM7*CN7/1000) -> 539.4685 | AR7: 0 | AS7: 0 | AT7: =AR7-AS7 -> 0 | AU7: =VLOOKUP(L7,'Spec Sheet (2)'!$A$4:$FI$9,165,0) -> solv.Less | AV7: =IF(H7="1PLY",0,IF(H7="2PLY",0,U7*CM7*CK7/1000))-2*IF(H7="1PLY",0,IF(H7="2PLY",0,U7*CM7*CK7/1000))/100 -> 1029 | AW7: 0 | AX7: 0 | AY7: =AW7-AX7 -> 0 | AZ7: =VLOOKUP(L7,'Spec Sheet (2)'!$A$4:$FJ$16684,166,0) -> Slitting | BA7: =IF(AK7="Slitting",AJ7,0)+IF(AP7="Slitting",AO7,0)+IF(AU7="Slitting",AT7,0)+IF(AZ7="Slitting",AY7,0) -> 0 | BB7: =VLOOKUP(L7,'Spec Sheet (2)'!$A$4:$AL$3749,38,0) -> 104399 | BC7: =VLOOKUP(L7,'Spec Sheet (2)'!$A$4:$O$26703,15,0) -> 1215mmX8Mic PET Chemical | BD7: =VLOOKUP(L7,'Spec Sheet (2)'!$A$4:$L$26703,11,0) -> 8 | BE7: =VLOOKUP(L7,'Spec Sheet (2)'!$A$4:$J$26703,9,0)/1000 -> 1.215 | BF7: =AB7*BE7*BD7*VLOOKUP(L7,'Spec Sheet (2)'!$A$4:$L$25803,12,0) -> 231.49606 | BG7: =IF(ISNA(VLOOKUP(BB7,'ALL STOCK'!$C$3:$N$990,12,0)),"-",VLOOKUP(BB7,'ALL STOCK'!$C$3:$N$990,12,0)) -> 4615.5 | BH7: =IF(ISNA(VLOOKUP(BB7,'ALL STOCK'!$C$3:$J$990,8,0)),"-",VLOOKUP(BB7,'ALL STOCK'!$C$3:$J$990,8,0)) -> 0 | BJ7: =VLOOKUP(L7,'Spec Sheet (2)'!$A$4:$AM$9,39,0) -> 104402 | BK7: =VLOOKUP(L7,'Spec Sheet (2)'!$A$4:$Z$26703,26,0) -> 1210mmx8mic Met Pet Chemical | BL7: =VLOOKUP(L7,'Spec Sheet (2)'!$A$4:$V$9,22,0) -> 8 | BM7: =VLOOKUP(L7,'Spec Sheet (2)'!$A$4:$T$26703,20,0)/1000 -> 1.21 | BN7: =AB7*BM7*CD7 -> 230.5434 | BO7: =IF(ISNA(VLOOKUP(BJ7,'ALL STOCK'!$C$4:$N$990,12,0)),"-",VLOOKUP(BJ7,'ALL STOCK'!$C$4:$N$990,12,0)) -> 4546.23 | BP7: =IF(ISNA(VLOOKUP(BJ7,'ALL STOCK'!$C$4:$J$990,8,0)),"-",VLOOKUP(BJ7,'ALL STOCK'!$C$4:$J$990,8,0)) -> 0 | BR7: =VLOOKUP(L7,'Spec Sheet (2)'!$A$4:$AN$9,40,0) -> 104432 | BS7: =VLOOKUP(L7,'Spec Sheet (2)'!$A$4:$FD$9,160,0) -> L | BT7: =VLOOKUP(L7,'Spec Sheet (2)'!$A$4:$AK$26703,37,0) -> 1215mmX 25mic PE (Natural) | BU7: =VLOOKUP(L7,'Spec Sheet (2)'!$A$4:$AG$26703,33,0) -> 25 | BV7: =VLOOKUP(L7,'Spec Sheet (2)'!$A$4:$AE$26703,31,0)/1000 -> 1.215 | BW7: =AB7*BV7*CE7 -> 475.3937 | BX7: =IF(ISNA(VLOOKUP(BR7,'ALL STOCK'!$C$3:$N$990,12,0)),"-",VLOOKUP(BR7,'ALL STOCK'!$C$3:$N$990,12,0)) -> 2304.6 | BY7: =IF(ISNA(VLOOKUP(BR7,'ALL STOCK'!$C$4:$J$990,8,)),"-",VLOOKUP(BR7,'ALL STOCK'!$C$4:$J$990,8,)) -> 5500 | BZ7: =VLOOKUP(L7,'Spec Sheet (2)'!$A$4:$B$25803,2,0) -> 1008 | CA7: =VLOOKUP(L7,'Spec Sheet (2)'!$A$4:$FO$25803,171,0) -> 3ply | CB7: =VLOOKUP(L7,'Spec Sheet (2)'!$A$4:$FF$9,161,0) -> L | CC7: =VLOOKUP(L7,'Spec Sheet (2)'!$A$4:$M$25803,13,0) -> 11.2 | CD7: =VLOOKUP(L7,'Spec Sheet (2)'!$A$4:$X$26703,24,0) -> 11.2 | CE7: =VLOOKUP(L7,'Spec Sheet (2)'!$A$4:$AI$25803,35,0) -> 23 | CF7: =VLOOKUP(L7,'Spec Sheet (2)'!$A$4:$BF$26703,58,0) -> 1.2 | CG7: =VLOOKUP(L7,'Spec Sheet (2)'!$A$4:$FN$25803,169,0) -> 2.5 | CH7: =VLOOKUP(L7,'Spec Sheet (2)'!$A$4:$FN$25803,170,0) -> 1.7 | CI7: =VLOOKUP(L7,'Spec Sheet (2)'!$A$4:$CX$26703,102,0) -> 0 | CJ7: =VLOOKUP(L7,'Spec Sheet (2)'!$A$4:$DC$26703,107,0) -> 0 | CK7: =SUM(CC7:CI7) -> 50.8 | CL7: =VLOOKUP(L7,'Spec Sheet (2)'!$A$4:$FL$26703,168,0) -> 1.05 | CM7: =VLOOKUP(L7,'Spec Sheet (2)'!$A$4:$I$26703,9,0) -> 1215 | CN7: =VLOOKUP(L7,'Spec Sheet (2)'!$A$4:$FP$26703,172,0) -> 26.1 | CO7: =VLOOKUP(L7,'Spec Sheet (2)'!$A$4:$D$26703,4,0) -> PARTY-4 | CQ7: =AQ7-AS7 -> 539.4685
A8: =K8 -> SO-5 | B8: =VLOOKUP(L8,'Spec Sheet (2)'!$A$4:$GD$26703,186,0) -> SPICE | F8: =VLOOKUP(L8,'Spec Sheet (2)'!$A$4:$S$9,19,0) -> Met Pet Corona | G8: =VLOOKUP(L8,'Spec Sheet (2)'!$A$4:$B$739,2,0) -> 1009 | H8: =VLOOKUP(K8,'ORDER BOOK'!$I$3:$W$18,15,0) -> 46141 | J8: =VLOOKUP(L8,'Spec Sheet (2)'!$A$4:$CV$26703,100,0) -> - | K8: SO-5 | L8: JOB NAME-5 | M8: =VLOOKUP(K8,'ORDER BOOK'!$I$3:$K$18,3,0) -> C-5 | O8: =IF(X8+AM8+AR8+AW8=0,"BAL",IF(AJ8+AO8+AT8+AY8=0,"COMPLETED","BAL")) -> BAL | P8: =IF(S8="KG",R8*Q8,R8/1000*Q8) -> 862.5 | Q8: 11.5 | R8: 75000 | S8: NO | T8: =(CC8+CF8)*P8*CL8/CK8 -> 217.64019 | U8: =T8/BE8/(CC8+CF8) -> 9.9515403 | V8: =(Y8*AE8*CK8)/1.06 -> 0 | W8: =+S8 -> NO | X8: 0 | Y8: =X8/BE8/(CC8+CF8) -> 0 | Z8: =IF(T8-X8>0,T8-X8,0) -> 217.64019 | AA8: =+S8 -> NO | AB8: =IF(U8-Y8>0,U8-Y8,0) -> 9.9515403 | AC8: =T8-AI8 -> 217.64019 | AD8: =AC8/BE8/(CC8+CF8) -> 9.9515403 | AE8: =VLOOKUP(L8,'Spec Sheet (2)'!$A$4:$BE$9,57,0)/1000 -> 1.2 | AF8: =IF(CI8>0,AB8,0) -> 0 | AG8: =(IF(BS8="B",AB8,0)+IF(CB8="B",AB8,0)) -> 0 | AH8: =(IF(BS8="L",AB8,0)+IF(CB8="L",AB8,0)) -> 19.903081 | AI8: 0 | AJ8: =X8-AI8 -> 0 | AK8: =VLOOKUP(L8,'Spec Sheet (2)'!$A$4:$FG$15742,163,0) -> solv.Less | AL8: =CM8*U8*CJ8/1000-3*CM8*U8*CJ8/1000/100 -> 0 | AM8: 0 | AN8: 0 | AO8: =AM8-AN8 -> 0 | AP8: =VLOOKUP(L8,'Spec Sheet (2)'!$A$4:$FH$9,164,0) -> 0 | AQ8: =(U8*CM8*CN8/1000) -> 440.11682 | AR8: 0 | AS8: 0 | AT8: =AR8-AS8 -> 0 | AU8: =VLOOKUP(L8,'Spec Sheet (2)'!$A$4:$FI$9,165,0) -> solv.Less | AV8: =IF(H8="1PLY",0,IF(H8="2PLY",0,U8*CM8*CK8/1000))-2*IF(H8="1PLY",0,IF(H8="2PLY",0,U8*CM8*CK8/1000))/100 -> 887.5125 | AW8: 0 | AX8: 0 | AY8: =AW8-AX8 -> 0 | AZ8: =VLOOKUP(L8,'Spec Sheet (2)'!$A$4:$FJ$16684,166,0) -> Slitting | BA8: =IF(AK8="Slitting",AJ8,0)+IF(AP8="Slitting",AO8,0)+IF(AU8="Slitting",AT8,0)+IF(AZ8="Slitting",AY8,0) -> 0 | BB8: =VLOOKUP(L8,'Spec Sheet (2)'!$A$4:$AL$3749,38,0) -> 100019 | BC8: =VLOOKUP(L8,'Spec Sheet (2)'!$A$4:$O$26703,15,0) -> 1215mmX12Mic PET Corona | BD8: =VLOOKUP(L8,'Spec Sheet (2)'!$A$4:$L$26703,11,0) -> 12 | BE8: =VLOOKUP(L8,'Spec Sheet (2)'!$A$4:$J$26703,9,0)/1000 -> 1.215 | BF8: =AB8*BE8*BD8*VLOOKUP(L8,'Spec Sheet (2)'!$A$4:$L$25803,12,0) -> 203.13084 | BG8: =IF(ISNA(VLOOKUP(BB8,'ALL STOCK'!$C$3:$N$990,12,0)),"-",VLOOKUP(BB8,'ALL STOCK'!$C$3:$N$990,12,0)) -> 3535.89 | BH8: =IF(ISNA(VLOOKUP(BB8,'ALL STOCK'!$C$3:$J$990,8,0)),"-",VLOOKUP(BB8,'ALL STOCK'!$C$3:$J$990,8,0)) -> 0 | BJ8: =VLOOKUP(L8,'Spec Sheet (2)'!$A$4:$AM$9,39,0) -> 104783 | BK8: =VLOOKUP(L8,'Spec Sheet (2)'!$A$4:$Z$26703,26,0) -> 1210mmx12mic Met Pet Corona | BL8: =VLOOKUP(L8,'Spec Sheet (2)'!$A$4:$V$9,22,0) -> 12 | BM8: =VLOOKUP(L8,'Spec Sheet (2)'!$A$4:$T$26703,20,0)/1000 -> 1.21 | BN8: =AB8*BM8*CD8 -> 202.29491 | BO8: =IF(ISNA(VLOOKUP(BJ8,'ALL STOCK'!$C$4:$N$990,12,0)),"-",VLOOKUP(BJ8,'ALL STOCK'!$C$4:$N$990,12,0)) -> 1000.84 | BP8: =IF(ISNA(VLOOKUP(BJ8,'ALL STOCK'!$C$4:$J$990,8,0)),"-",VLOOKUP(BJ8,'ALL STOCK'!$C$4:$J$990,8,0)) -> 0 | BR8: =VLOOKUP(L8,'Spec Sheet (2)'!$A$4:$AN$9,40,0) -> 104847 | BS8: =VLOOKUP(L8,'Spec Sheet (2)'!$A$4:$FD$9,160,0) -> L | BT8: =VLOOKUP(L8,'Spec Sheet (2)'!$A$4:$AK$26703,37,0) -> 1215mmX 40mic PE (Natural) | BU8: =VLOOKUP(L8,'Spec Sheet (2)'!$A$4:$AG$26703,33,0) -> 40 | BV8: =VLOOKUP(L8,'Spec Sheet (2)'!$A$4:$AE$26703,31,0)/1000 -> 1.215 | BW8: =AB8*BV8*CE8 -> 444.95327 | BX8: =IF(ISNA(VLOOKUP(BR8,'ALL STOCK'!$C$3:$N$990,12,0)),"-",VLOOKUP(BR8,'ALL STOCK'!$C$3:$N$990,12,0)) -> 109.2 | BY8: =IF(ISNA(VLOOKUP(BR8,'ALL STOCK'!$C$4:$J$990,8,)),"-",VLOOKUP(BR8,'ALL STOCK'!$C$4:$J$990,8,)) -> 0 | BZ8: =VLOOKUP(L8,'Spec Sheet (2)'!$A$4:$B$25803,2,0) -> 1009 | CA8: =VLOOKUP(L8,'Spec Sheet (2)'!$A$4:$FO$25803,171,0) -> 3ply | CB8: =VLOOKUP(L8,'Spec Sheet (2)'!$A$4:$FF$9,161,0) -> L | CC8: =VLOOKUP(L8,'Spec Sheet (2)'!$A$4:$M$25803,13,0) -> 16.8 | CD8: =VLOOKUP(L8,'Spec Sheet (2)'!$A$4:$X$26703,24,0) -> 16.8 | CE8: =VLOOKUP(L8,'Spec Sheet (2)'!$A$4:$AI$25803,35,0) -> 36.8 | CF8: =VLOOKUP(L8,'Spec Sheet (2)'!$A$4:$BF$26703,58,0) -> 1.2 | CG8: =VLOOKUP(L8,'Spec Sheet (2)'!$A$4:$FN$25803,169,0) -> 1.6 | CH8: =VLOOKUP(L8,'Spec Sheet (2)'!$A$4:$FN$25803,170,0) -> 1.7 | CI8: =VLOOKUP(L8,'Spec Sheet (2)'!$A$4:$CX$26703,102,0) -> 0 | CJ8: =VLOOKUP(L8,'Spec Sheet (2)'!$A$4:$DC$26703,107,0) -> 0 | CK8: =SUM(CC8:CI8) -> 74.9 | CL8: =VLOOKUP(L8,'Spec Sheet (2)'!$A$4:$FL$26703,168,0) -> 1.05 | CM8: =VLOOKUP(L8,'Spec Sheet (2)'!$A$4:$I$26703,9,0) -> 1215 | CN8: =VLOOKUP(L8,'Spec Sheet (2)'!$A$4:$FP$26703,172,0) -> 36.4 | CO8: =VLOOKUP(L8,'Spec Sheet (2)'!$A$4:$D$26703,4,0) -> PARTY-5 | CQ8: =AQ8-AS8 -> 440.11682
A9: =K9 -> SO-6 | B9: =VLOOKUP(L9,'Spec Sheet (2)'!$A$4:$GD$26703,186,0) -> FLOW WRAP | F9: =VLOOKUP(L9,'Spec Sheet (2)'!$A$4:$S$9,19,0) -> PE (White) | G9: =VLOOKUP(L9,'Spec Sheet (2)'!$A$4:$B$739,2,0) -> 1010 | H9: =VLOOKUP(K9,'ORDER BOOK'!$I$3:$W$18,15,0) -> 46141 | J9: =VLOOKUP(L9,'Spec Sheet (2)'!$A$4:$CV$26703,100,0) -> - | K9: SO-6 | L9: JOB NAME-6 | M9: =VLOOKUP(K9,'ORDER BOOK'!$I$3:$K$18,3,0) -> C-6 | O9: =IF(X9+AM9+AR9+AW9=0,"BAL",IF(AJ9+AO9+AT9+AY9=0,"COMPLETED","BAL")) -> BAL | P9: =IF(S9="KG",R9*Q9,R9/1000*Q9) -> 1000 | Q9: 1 | R9: 1000 | S9: KG | T9: =(CC9+CF9)*P9*CL9/CK9 -> 358.98285 | U9: =T9/BE9/(CC9+CF9) -> 17.163894 | V9: =(Y9*AE9*CK9)/1.06 -> 0 | W9: =+S9 -> KG | X9: 0 | Y9: =X9/BE9/(CC9+CF9) -> 0 | Z9: =IF(T9-X9>0,T9-X9,0) -> 358.98285 | AA9: =+S9 -> KG | AB9: =IF(U9-Y9>0,U9-Y9,0) -> 17.163894 | AC9: =T9-AI9 -> 358.98285 | AD9: =AC9/BE9/(CC9+CF9) -> 17.163894 | AE9: =VLOOKUP(L9,'Spec Sheet (2)'!$A$4:$BE$9,57,0)/1000 -> 1.16 | AF9: =IF(CI9>0,AB9,0) -> 0 | AG9: =(IF(BS9="B",AB9,0)+IF(CB9="B",AB9,0)) -> 17.163894 | AH9: =(IF(BS9="L",AB9,0)+IF(CB9="L",AB9,0)) -> 0 | AI9: 0 | AJ9: =X9-AI9 -> 0 | AK9: =VLOOKUP(L9,'Spec Sheet (2)'!$A$4:$FG$15742,163,0) -> solv.Less | AL9: =CM9*U9*CJ9/1000-3*CM9*U9*CJ9/1000/100 -> 0 | AM9: 0 | AN9: 0 | AO9: =AM9-AN9 -> 0 | AP9: =VLOOKUP(L9,'Spec Sheet (2)'!$A$4:$FH$9,164,0) -> 0 | AQ9: =(U9*CM9*CN9/1000) -> 1035 | AR9: 0 | AS9: 0 | AT9: =AR9-AS9 -> 0 | AU9: =VLOOKUP(L9,'Spec Sheet (2)'!$A$4:$FI$9,165,0) -> Slitting | AV9: =IF(H9="1PLY",0,IF(H9="2PLY",0,U9*CM9*CK9/1000))-2*IF(H9="1PLY",0,IF(H9="2PLY",0,U9*CM9*CK9/1000))/100 -> 1014.3 | AW9: 0 | AX9: 0 | AY9: =AW9-AX9 -> 0 | AZ9: =VLOOKUP(L9,'Spec Sheet (2)'!$A$4:$FJ$16684,166,0) -> 0 | BA9: =IF(AK9="Slitting",AJ9,0)+IF(AP9="Slitting",AO9,0)+IF(AU9="Slitting",AT9,0)+IF(AZ9="Slitting",AY9,0) -> 0 | BB9: =VLOOKUP(L9,'Spec Sheet (2)'!$A$4:$AL$3749,38,0) -> 100393 | BC9: =VLOOKUP(L9,'Spec Sheet (2)'!$A$4:$O$26703,15,0) -> 1175mmX12Mic PET Corona | BD9: =VLOOKUP(L9,'Spec Sheet (2)'!$A$4:$L$26703,11,0) -> 12 | BE9: =VLOOKUP(L9,'Spec Sheet (2)'!$A$4:$J$26703,9,0)/1000 -> 1.175 | BF9: =AB9*BE9*BD9*VLOOKUP(L9,'Spec Sheet (2)'!$A$4:$L$25803,12,0) -> 338.81528 | BG9: =IF(ISNA(VLOOKUP(BB9,'ALL STOCK'!$C$3:$N$990,12,0)),"-",VLOOKUP(BB9,'ALL STOCK'!$C$3:$N$990,12,0)) -> 1632.64 | BH9: =IF(ISNA(VLOOKUP(BB9,'ALL STOCK'!$C$3:$J$990,8,0)),"-",VLOOKUP(BB9,'ALL STOCK'!$C$3:$J$990,8,0)) -> 0 | BJ9: =VLOOKUP(L9,'Spec Sheet (2)'!$A$4:$AM$9,39,0) -> 0 | BK9: =VLOOKUP(L9,'Spec Sheet (2)'!$A$4:$Z$26703,26,0) -> 1175mmx33mic PE (White) | BL9: =VLOOKUP(L9,'Spec Sheet (2)'!$A$4:$V$9,22,0) -> 33 | BM9: =VLOOKUP(L9,'Spec Sheet (2)'!$A$4:$T$26703,20,0)/1000 -> 1.175 | BN9: =AB9*BM9*CD9 -> 625.59821 | BO9: =IF(ISNA(VLOOKUP(BJ9,'ALL STOCK'!$C$4:$N$990,12,0)),"-",VLOOKUP(BJ9,'ALL STOCK'!$C$4:$N$990,12,0)) -> - | BP9: =IF(ISNA(VLOOKUP(BJ9,'ALL STOCK'!$C$4:$J$990,8,0)),"-",VLOOKUP(BJ9,'ALL STOCK'!$C$4:$J$990,8,0)) -> - | BR9: =VLOOKUP(L9,'Spec Sheet (2)'!$A$4:$AN$9,40,0) -> 0 | BS9: =VLOOKUP(L9,'Spec Sheet (2)'!$A$4:$FD$9,160,0) -> B | BT9: =VLOOKUP(L9,'Spec Sheet (2)'!$A$4:$AK$26703,37,0) -> mmX mic | BU9: =VLOOKUP(L9,'Spec Sheet (2)'!$A$4:$AG$26703,33,0) -> 0 | BV9: =VLOOKUP(L9,'Spec Sheet (2)'!$A$4:$AE$26703,31,0)/1000 -> 0 | BW9: =AB9*BV9*CE9 -> 0 | BX9: =IF(ISNA(VLOOKUP(BR9,'ALL STOCK'!$C$3:$N$990,12,0)),"-",VLOOKUP(BR9,'ALL STOCK'!$C$3:$N$990,12,0)) -> - | BY9: =IF(ISNA(VLOOKUP(BR9,'ALL STOCK'!$C$4:$J$990,8,)),"-",VLOOKUP(BR9,'ALL STOCK'!$C$4:$J$990,8,)) -> - | BZ9: =VLOOKUP(L9,'Spec Sheet (2)'!$A$4:$B$25803,2,0) -> 1010 | CA9: =VLOOKUP(L9,'Spec Sheet (2)'!$A$4:$FO$25803,171,0) -> 2PLY | CB9: =VLOOKUP(L9,'Spec Sheet (2)'!$A$4:$FF$9,161,0) -> X | CC9: =VLOOKUP(L9,'Spec Sheet (2)'!$A$4:$M$25803,13,0) -> 16.8 | CD9: =VLOOKUP(L9,'Spec Sheet (2)'!$A$4:$X$26703,24,0) -> 31.02 | CE9: =VLOOKUP(L9,'Spec Sheet (2)'!$A$4:$AI$25803,35,0) -> 0 | CF9: =VLOOKUP(L9,'Spec Sheet (2)'!$A$4:$BF$26703,58,0) -> 1 | CG9: =VLOOKUP(L9,'Spec Sheet (2)'!$A$4:$FN$25803,169,0) -> 2.5 | CH9: =VLOOKUP(L9,'Spec Sheet (2)'!$A$4:$FN$25803,170,0) -> 0 | CI9: =VLOOKUP(L9,'Spec Sheet (2)'!$A$4:$CX$26703,102,0) -> 0 | CJ9: =VLOOKUP(L9,'Spec Sheet (2)'!$A$4:$DC$26703,107,0) -> 0 | CK9: =SUM(CC9:CI9) -> 51.32 | CL9: =VLOOKUP(L9,'Spec Sheet (2)'!$A$4:$FL$26703,168,0) -> 1.035 | CM9: =VLOOKUP(L9,'Spec Sheet (2)'!$A$4:$I$26703,9,0) -> 1175 | CN9: =VLOOKUP(L9,'Spec Sheet (2)'!$A$4:$FP$26703,172,0) -> 51.32 | CO9: =VLOOKUP(L9,'Spec Sheet (2)'!$A$4:$D$26703,4,0) -> PARTY-6 | CQ9: =AQ9-AS9 -> 1035
A10: =K10 -> 0 | B10: =VLOOKUP(L10,'Spec Sheet (2)'!$A$4:$GD$26703,186,0) -> #N/A | F10: =VLOOKUP(L10,'Spec Sheet (2)'!$A$4:$S$9,19,0) -> #N/A | G10: =VLOOKUP(L10,'Spec Sheet (2)'!$A$4:$B$739,2,0) -> #N/A | H10: =VLOOKUP(K10,'ORDER BOOK'!$I$3:$W$18,15,0) -> #N/A | J10: =VLOOKUP(L10,'Spec Sheet (2)'!$A$4:$CV$26703,100,0) -> #N/A | M10: =VLOOKUP(K10,'ORDER BOOK'!$I$3:$K$18,3,0) -> #N/A | O10: =IF(X10+AM10+AR10+AW10=0,"BAL",IF(AJ10+AO10+AT10+AY10=0,"COMPLETED","BAL")) -> BAL | P10: =IF(S10="KG",R10*Q10,R10/1000*Q10) -> 0 | Q10: 1 | S10: KG | T10: =(CC10+CF10)*P10*CL10/CK10 -> #N/A | U10: =T10/BE10/(CC10+CF10) -> #N/A | V10: =(Y10*AE10*CK10)/1.06 -> #N/A | W10: =+S10 -> KG | X10: 0 | Y10: =X10/BE10/(CC10+CF10) -> #N/A | Z10: =IF(T10-X10>0,T10-X10,0) -> #N/A | AA10: =+S10 -> KG | AB10: =IF(U10-Y10>0,U10-Y10,0) -> #N/A | AC10: =T10-AI10 -> #N/A | AD10: =AC10/BE10/(CC10+CF10) -> #N/A | AE10: =VLOOKUP(L10,'Spec Sheet (2)'!$A$4:$BE$9,57,0)/1000 -> #N/A | AF10: =IF(CI10>0,AB10,0) -> #N/A | AG10: =(IF(BS10="B",AB10,0)+IF(CB10="B",AB10,0)) -> #N/A | AH10: =(IF(BS10="L",AB10,0)+IF(CB10="L",AB10,0)) -> #N/A | AI10: 0 | AJ10: =X10-AI10 -> 0 | AK10: =VLOOKUP(L10,'Spec Sheet (2)'!$A$4:$FG$15742,163,0) -> #N/A | AL10: =CM10*U10*CJ10/1000-3*CM10*U10*CJ10/1000/100 -> #N/A | AM10: 0 | AN10: 0 | AO10: =AM10-AN10 -> 0 | AP10: =VLOOKUP(L10,'Spec Sheet (2)'!$A$4:$FH$9,164,0) -> #N/A | AQ10: =(U10*CM10*CN10/1000) -> #N/A | AR10: 0 | AS10: 0 | AT10: =AR10-AS10 -> 0 | AU10: =VLOOKUP(L10,'Spec Sheet (2)'!$A$4:$FI$9,165,0) -> #N/A | AV10: =IF(H10="1PLY",0,IF(H10="2PLY",0,U10*CM10*CK10/1000))-2*IF(H10="1PLY",0,IF(H10="2PLY",0,U10*CM10*CK10/1000))/100 -> #N/A | AW10: 0 | AX10: 0 | AY10: =AW10-AX10 -> 0 | AZ10: =VLOOKUP(L10,'Spec Sheet (2)'!$A$4:$FJ$16684,166,0) -> #N/A | BA10: =IF(AK10="Slitting",AJ10,0)+IF(AP10="Slitting",AO10,0)+IF(AU10="Slitting",AT10,0)+IF(AZ10="Slitting",AY10,0) -> #N/A | BB10: =VLOOKUP(L10,'Spec Sheet (2)'!$A$4:$AL$3749,38,0) -> #N/A | BC10: =VLOOKUP(L10,'Spec Sheet (2)'!$A$4:$O$26703,15,0) -> #N/A | BD10: =VLOOKUP(L10,'Spec Sheet (2)'!$A$4:$L$26703,11,0) -> #N/A | BE10: =VLOOKUP(L10,'Spec Sheet (2)'!$A$4:$J$26703,9,0)/1000 -> #N/A | BF10: =AB10*BE10*BD10*VLOOKUP(L10,'Spec Sheet (2)'!$A$4:$L$25803,12,0) -> #N/A | BG10: =IF(ISNA(VLOOKUP(BB10,'ALL STOCK'!$C$3:$N$990,12,0)),"-",VLOOKUP(BB10,'ALL STOCK'!$C$3:$N$990,12,0)) -> - | BH10: =IF(ISNA(VLOOKUP(BB10,'ALL STOCK'!$C$3:$J$990,8,0)),"-",VLOOKUP(BB10,'ALL STOCK'!$C$3:$J$990,8,0)) -> - | BJ10: =VLOOKUP(L10,'Spec Sheet (2)'!$A$4:$AM$9,39,0) -> #N/A | BK10: =VLOOKUP(L10,'Spec Sheet (2)'!$A$4:$Z$26703,26,0) -> #N/A | BL10: =VLOOKUP(L10,'Spec Sheet (2)'!$A$4:$V$9,22,0) -> #N/A | BM10: =VLOOKUP(L10,'Spec Sheet (2)'!$A$4:$T$26703,20,0)/1000 -> #N/A | BN10: =AB10*BM10*CD10 -> #N/A | BO10: =IF(ISNA(VLOOKUP(BJ10,'ALL STOCK'!$C$4:$N$990,12,0)),"-",VLOOKUP(BJ10,'ALL STOCK'!$C$4:$N$990,12,0)) -> - | BP10: =IF(ISNA(VLOOKUP(BJ10,'ALL STOCK'!$C$4:$J$990,8,0)),"-",VLOOKUP(BJ10,'ALL STOCK'!$C$4:$J$990,8,0)) -> - | BR10: =VLOOKUP(L10,'Spec Sheet (2)'!$A$4:$AN$9,40,0) -> #N/A | BS10: =VLOOKUP(L10,'Spec Sheet (2)'!$A$4:$FD$9,160,0) -> #N/A | BT10: =VLOOKUP(L10,'Spec Sheet (2)'!$A$4:$AK$26703,37,0) -> #N/A | BU10: =VLOOKUP(L10,'Spec Sheet (2)'!$A$4:$AG$26703,33,0) -> #N/A | BV10: =VLOOKUP(L10,'Spec Sheet (2)'!$A$4:$AE$26703,31,0)/1000 -> #N/A | BW10: =AB10*BV10*CE10 -> #N/A | BX10: =IF(ISNA(VLOOKUP(BR10,'ALL STOCK'!$C$3:$N$990,12,0)),"-",VLOOKUP(BR10,'ALL STOCK'!$C$3:$N$990,12,0)) -> - | BY10: =IF(ISNA(VLOOKUP(BR10,'ALL STOCK'!$C$4:$J$990,8,)),"-",VLOOKUP(BR10,'ALL STOCK'!$C$4:$J$990,8,)) -> - | BZ10: =VLOOKUP(L10,'Spec Sheet (2)'!$A$4:$B$25803,2,0) -> #N/A | CA10: =VLOOKUP(L10,'Spec Sheet (2)'!$A$4:$FO$25803,171,0) -> #N/A | CB10: =VLOOKUP(L10,'Spec Sheet (2)'!$A$4:$FF$9,161,0) -> #N/A | CC10: =VLOOKUP(L10,'Spec Sheet (2)'!$A$4:$M$25803,13,0) -> #N/A | CD10: =VLOOKUP(L10,'Spec Sheet (2)'!$A$4:$X$26703,24,0) -> #N/A | CE10: =VLOOKUP(L10,'Spec Sheet (2)'!$A$4:$AI$25803,35,0) -> #N/A | CF10: =VLOOKUP(L10,'Spec Sheet (2)'!$A$4:$BF$26703,58,0) -> #N/A | CG10: =VLOOKUP(L10,'Spec Sheet (2)'!$A$4:$FN$25803,169,0) -> #N/A | CH10: =VLOOKUP(L10,'Spec Sheet (2)'!$A$4:$FN$25803,170,0) -> #N/A | CI10: =VLOOKUP(L10,'Spec Sheet (2)'!$A$4:$CX$26703,102,0) -> #N/A | CJ10: =VLOOKUP(L10,'Spec Sheet (2)'!$A$4:$DC$26703,107,0) -> #N/A | CK10: =SUM(CC10:CI10) -> #N/A | CL10: =VLOOKUP(L10,'Spec Sheet (2)'!$A$4:$FL$26703,168,0) -> #N/A | CM10: =VLOOKUP(L10,'Spec Sheet (2)'!$A$4:$I$26703,9,0) -> #N/A | CN10: =VLOOKUP(L10,'Spec Sheet (2)'!$A$4:$FP$26703,172,0) -> #N/A | CO10: =VLOOKUP(L10,'Spec Sheet (2)'!$A$4:$D$26703,4,0) -> #N/A | CQ10: =AQ10-AS10 -> #N/A
A11: =K11 -> 0 | B11: =VLOOKUP(L11,'Spec Sheet (2)'!$A$4:$GD$26703,186,0) -> #N/A | F11: =VLOOKUP(L11,'Spec Sheet (2)'!$A$4:$S$9,19,0) -> #N/A | G11: =VLOOKUP(L11,'Spec Sheet (2)'!$A$4:$B$739,2,0) -> #N/A | H11: =VLOOKUP(K11,'ORDER BOOK'!$I$3:$W$18,15,0) -> #N/A | J11: =VLOOKUP(L11,'Spec Sheet (2)'!$A$4:$CV$26703,100,0) -> #N/A | M11: =VLOOKUP(K11,'ORDER BOOK'!$I$3:$K$18,3,0) -> #N/A | O11: =IF(X11+AM11+AR11+AW11=0,"BAL",IF(AJ11+AO11+AT11+AY11=0,"COMPLETED","BAL")) -> BAL | P11: =IF(S11="KG",R11*Q11,R11/1000*Q11) -> 0 | Q11: 1 | S11: KG | T11: =(CC11+CF11)*P11*CL11/CK11 -> #N/A | U11: =T11/BE11/(CC11+CF11) -> #N/A | V11: =(Y11*AE11*CK11)/1.06 -> #N/A | W11: =+S11 -> KG | X11: 0 | Y11: =X11/BE11/(CC11+CF11) -> #N/A | Z11: =IF(T11-X11>0,T11-X11,0) -> #N/A | AA11: =+S11 -> KG | AB11: =IF(U11-Y11>0,U11-Y11,0) -> #N/A | AC11: =T11-AI11 -> #N/A | AD11: =AC11/BE11/(CC11+CF11) -> #N/A | AE11: =VLOOKUP(L11,'Spec Sheet (2)'!$A$4:$BE$9,57,0)/1000 -> #N/A | AF11: =IF(CI11>0,AB11,0) -> #N/A | AG11: =(IF(BS11="B",AB11,0)+IF(CB11="B",AB11,0)) -> #N/A | AH11: =(IF(BS11="L",AB11,0)+IF(CB11="L",AB11,0)) -> #N/A | AI11: 0 | AJ11: =X11-AI11 -> 0 | AK11: =VLOOKUP(L11,'Spec Sheet (2)'!$A$4:$FG$15742,163,0) -> #N/A | AL11: =CM11*U11*CJ11/1000-3*CM11*U11*CJ11/1000/100 -> #N/A | AM11: 0 | AN11: 0 | AO11: =AM11-AN11 -> 0 | AP11: =VLOOKUP(L11,'Spec Sheet (2)'!$A$4:$FH$9,164,0) -> #N/A | AQ11: =(U11*CM11*CN11/1000) -> #N/A | AR11: 0 | AS11: 0 | AT11: =AR11-AS11 -> 0 | AU11: =VLOOKUP(L11,'Spec Sheet (2)'!$A$4:$FI$9,165,0) -> #N/A | AV11: =IF(H11="1PLY",0,IF(H11="2PLY",0,U11*CM11*CK11/1000))-2*IF(H11="1PLY",0,IF(H11="2PLY",0,U11*CM11*CK11/1000))/100 -> #N/A | AW11: 0 | AX11: 0 | AY11: =AW11-AX11 -> 0 | AZ11: =VLOOKUP(L11,'Spec Sheet (2)'!$A$4:$FJ$16684,166,0) -> #N/A | BA11: =IF(AK11="Slitting",AJ11,0)+IF(AP11="Slitting",AO11,0)+IF(AU11="Slitting",AT11,0)+IF(AZ11="Slitting",AY11,0) -> #N/A | BB11: =VLOOKUP(L11,'Spec Sheet (2)'!$A$4:$AL$3749,38,0) -> #N/A | BC11: =VLOOKUP(L11,'Spec Sheet (2)'!$A$4:$O$26703,15,0) -> #N/A | BD11: =VLOOKUP(L11,'Spec Sheet (2)'!$A$4:$L$26703,11,0) -> #N/A | BE11: =VLOOKUP(L11,'Spec Sheet (2)'!$A$4:$J$26703,9,0)/1000 -> #N/A | BF11: =AB11*BE11*BD11*VLOOKUP(L11,'Spec Sheet (2)'!$A$4:$L$25803,12,0) -> #N/A | BG11: =IF(ISNA(VLOOKUP(BB11,'ALL STOCK'!$C$3:$N$990,12,0)),"-",VLOOKUP(BB11,'ALL STOCK'!$C$3:$N$990,12,0)) -> - | BH11: =IF(ISNA(VLOOKUP(BB11,'ALL STOCK'!$C$3:$J$990,8,0)),"-",VLOOKUP(BB11,'ALL STOCK'!$C$3:$J$990,8,0)) -> - | BJ11: =VLOOKUP(L11,'Spec Sheet (2)'!$A$4:$AM$9,39,0) -> #N/A | BK11: =VLOOKUP(L11,'Spec Sheet (2)'!$A$4:$Z$26703,26,0) -> #N/A | BL11: =VLOOKUP(L11,'Spec Sheet (2)'!$A$4:$V$9,22,0) -> #N/A | BM11: =VLOOKUP(L11,'Spec Sheet (2)'!$A$4:$T$26703,20,0)/1000 -> #N/A | BN11: =AB11*BM11*CD11 -> #N/A | BO11: =IF(ISNA(VLOOKUP(BJ11,'ALL STOCK'!$C$4:$N$990,12,0)),"-",VLOOKUP(BJ11,'ALL STOCK'!$C$4:$N$990,12,0)) -> - | BP11: =IF(ISNA(VLOOKUP(BJ11,'ALL STOCK'!$C$4:$J$990,8,0)),"-",VLOOKUP(BJ11,'ALL STOCK'!$C$4:$J$990,8,0)) -> - | BR11: =VLOOKUP(L11,'Spec Sheet (2)'!$A$4:$AN$9,40,0) -> #N/A | BS11: =VLOOKUP(L11,'Spec Sheet (2)'!$A$4:$FD$9,160,0) -> #N/A | BT11: =VLOOKUP(L11,'Spec Sheet (2)'!$A$4:$AK$26703,37,0) -> #N/A | BU11: =VLOOKUP(L11,'Spec Sheet (2)'!$A$4:$AG$26703,33,0) -> #N/A | BV11: =VLOOKUP(L11,'Spec Sheet (2)'!$A$4:$AE$26703,31,0)/1000 -> #N/A | BW11: =AB11*BV11*CE11 -> #N/A | BX11: =IF(ISNA(VLOOKUP(BR11,'ALL STOCK'!$C$3:$N$990,12,0)),"-",VLOOKUP(BR11,'ALL STOCK'!$C$3:$N$990,12,0)) -> - | BY11: =IF(ISNA(VLOOKUP(BR11,'ALL STOCK'!$C$4:$J$990,8,)),"-",VLOOKUP(BR11,'ALL STOCK'!$C$4:$J$990,8,)) -> - | BZ11: =VLOOKUP(L11,'Spec Sheet (2)'!$A$4:$B$25803,2,0) -> #N/A | CA11: =VLOOKUP(L11,'Spec Sheet (2)'!$A$4:$FO$25803,171,0) -> #N/A | CB11: =VLOOKUP(L11,'Spec Sheet (2)'!$A$4:$FF$9,161,0) -> #N/A | CC11: =VLOOKUP(L11,'Spec Sheet (2)'!$A$4:$M$25803,13,0) -> #N/A | CD11: =VLOOKUP(L11,'Spec Sheet (2)'!$A$4:$X$26703,24,0) -> #N/A | CE11: =VLOOKUP(L11,'Spec Sheet (2)'!$A$4:$AI$25803,35,0) -> #N/A | CF11: =VLOOKUP(L11,'Spec Sheet (2)'!$A$4:$BF$26703,58,0) -> #N/A | CG11: =VLOOKUP(L11,'Spec Sheet (2)'!$A$4:$FN$25803,169,0) -> #N/A | CH11: =VLOOKUP(L11,'Spec Sheet (2)'!$A$4:$FN$25803,170,0) -> #N/A | CI11: =VLOOKUP(L11,'Spec Sheet (2)'!$A$4:$CX$26703,102,0) -> #N/A | CJ11: =VLOOKUP(L11,'Spec Sheet (2)'!$A$4:$DC$26703,107,0) -> #N/A | CK11: =SUM(CC11:CI11) -> #N/A | CL11: =VLOOKUP(L11,'Spec Sheet (2)'!$A$4:$FL$26703,168,0) -> #N/A | CM11: =VLOOKUP(L11,'Spec Sheet (2)'!$A$4:$I$26703,9,0) -> #N/A | CN11: =VLOOKUP(L11,'Spec Sheet (2)'!$A$4:$FP$26703,172,0) -> #N/A | CO11: =VLOOKUP(L11,'Spec Sheet (2)'!$A$4:$D$26703,4,0) -> #N/A | CQ11: =AQ11-AS11 -> #N/A

Sheet PRINTING PLAN
A1: 0 | B1: 277 | C1: MANJUSHREE INNOVATION PVT LTD | O1: MIPL / PRD / FOR / 107 VER: 05; REV: 04 DATE: 16.11.2024
A2: =TODAY() -> 46146 | C2: MACHINE PLAN PRINTING
A3: RM Status | B3: SO/ no. | C3: JOB NAME | D3: WO/ no | E3: PPC Priority | F3: (Promo/PKD/Address/MRP) | G3: FG Code | H3: Devition RM / Remarks | I3: Specification | J3: Printed Film OUTPUT-KG | K3: Printed Film OUTPUT-KM | L3: PLY | M3: JCO Hrs | N3: Avg MPM | O3: Run Time Hrs | P3: ORDER | Q3: SO DATE | R3: DELIVERY DATE | S3: Remarks | T3: FROM | U3: TO
A4: PELICAN_ 1
A6: AVL | B6: SO-1 | C6: JOB NAME-1 | D6: =VLOOKUP(B6,'ORDER BOOK'!$I$3:$K$18,3,0) -> C-1 | G6: =VLOOKUP(C6,'Spec Sheet (2)'!$A$4:$B$20737,2,0) -> 1005 | I6: =VLOOKUP(C6,'Spec Sheet (2)'!$A$4:$O$26649,15,0) -> 1125mmX12Mic PET Chemical | J6: =VLOOKUP(B6,'PENDING ORDER'!$K$4:$Z$2510,16,0) -> 0 | K6: =VLOOKUP(B6,'PENDING ORDER'!$K$2:$AB$2510,18,0) -> 0 | L6: =VLOOKUP(C6,'Spec Sheet (2)'!$A$4:$FO$26829,171,0) -> 4PLY | M6: 1 | N6: 375 | O6: =(K6*1000/N6/60)+M6 -> 1 | P6: =VLOOKUP(B6,'ORDER BOOK'!$I$3:$Q$18,9,0)/1000 -> 1 | Q6: =VLOOKUP(B6,'ORDER BOOK'!$I$3:$W$18,15,0) -> 46141 | R6: =VLOOKUP(B6,'ORDER BOOK'!$I$3:$Z$18,16,0) -> 46157 | S6: NORD | T6: 46142.292 | U6: =T6+O6/24 -> 46142.333
